Workbook

Sheet סיכום -  סניפים ומחלקות
B3: רשת - מסכם | C3: 8.25 | D3: 9.25 | E3: 10.25 | F3: 11.25 | G3: 12.25 | H3: 1.26 | I3: 2.26 | J3: 3.26 | K3: 4.26
B4: הכנסות | C4: =+C19+C145+C159+C173+C187 -> 4676893.4 | D4: =+D19+D145+D159+D173+D187 -> 5133633.9 | E4: =+E19+E145+E159+E173+E187 -> 5831123.7 | F4: =+F19+F145+F159+F173+F187 -> 6376266.9 | G4: =+G19+G145+G159+G173+G187 -> 6032676.3 | H4: =+H19+H145+H159+H173+H187 -> 6116191.5 | I4: =+I19+I145+I159+I173+I187 -> 5789351.3 | J4: =+J19+J145+J159+J173+J187 -> 5461910 | K4: =+K19+K145+K159+K173+K187 -> 6209433.3
B5: שכר רופאים | C5: =+C20+C146+F160+C174+C188 -> 835644.76 | D5: =+D20+D146+G160+D174+D188 -> 1609293.6 | E5: =+E20+E146+E160+E174+E188 -> 1969776.5 | F5: =+F20+F146+F160+F174+F188 -> 1935184.8 | G5: =+G20+G146+G160+G174+G188 -> 2292739.6 | H5: =+H20+H146+H160+H174+H188 -> 1987508 | I5: =+I20+I146+I160+I174+I188 -> 1896357.9 | J5: =+J20+J146+J160+J174+J188 -> 2245276.1 | K5: =+K20+K146+K160+K174+K188 -> 2210159.5
B6: % | C6: =+C5/C4 -> 0.17867518 | D6: =+D5/D4 -> 0.3134804 | E6: =+E5/E4 -> 0.33780393 | F6: =+F5/F4 -> 0.30349809 | G6: =+G5/G4 -> 0.38005348 | H6: =+H5/H4 -> 0.32495843 | I6: =+I5/I4 -> 0.32755966 | J6: =+J5/J4 -> 0.41107894 | K6: =+K5/K4 -> 0.35593578
B7: שכר עובדים | C7: =+C22+C148+C162+C176+C190 -> 487724.95 | D7: =+D22+D148+D162+D176+D190 -> 1422891.2 | E7: =+E22+E148+E162+E176+E190 -> 1612541.1 | F7: =+F22+F148+F162+F176+F190 -> 1459346 | G7: =+G22+G148+G162+G176+G190 -> 1607418.7 | H7: =+H22+H148+H162+H176+H190 -> 1490888.2 | I7: =+I22+I148+I162+I176+I190 -> 1507303.8 | J7: =+J22+J148+J162+J176+J190 -> 1534633.6 | K7: =+K22+K148+K162+K176+K190 -> 1799184.9
B8: % | C8: =+C7/C4 -> 0.10428396 | D8: =+D7/D4 -> 0.27717037 | E8: =+E7/E4 -> 0.27654037 | F8: =+F7/F4 -> 0.22887153 | G8: =+G7/G4 -> 0.26645201 | H8: =+H7/H4 -> 0.24376088 | I8: =+I7/I4 -> 0.26035798 | J8: =+J7/J4 -> 0.28097013 | K8: =+K7/K4 -> 0.28975026
B9: קבלני משנה - ספקים | C9: =+C24+C150+C164+C178+C192 -> 0 | D9: =+D24+D150+D164+D178+D192 -> 0 | E9: =+E24+E150+E164+E178+E192 -> 53839 | F9: =+F24+F150+F164+F178+F192 -> 50246 | G9: =+G24+G150+G164+G178+G192 -> 56588.881 | H9: =+H24+H150+H164+H178+H192 -> 64173 | I9: =+I24+I150+I164+I178+I192 -> 53500 | J9: =+J24+J150+J164+J178+J192 -> 50675.424 | K9: =+K24+K150+K164+K178+K192 -> 43656.763
B10: % | C10: =+C9/C4 -> 0 | D10: =+D9/D4 -> 0 | E10: =+E9/E4 -> 0.0092330402 | F10: =+F9/F4 -> 0.0078801594 | G10: =+G9/G4 -> 0.0093803942 | H10: =+H9/H4 -> 0.010492314 | I10: =+I9/I4 -> 0.0092411045 | J10: =+J9/J4 -> 0.0092779676 | K10: =+K9/K4 -> 0.0070307161
B11: וטמרקט | C11: =+C26+C152+C166+C180+C194 -> 0 | D11: =+D26+D152+D166+D180+D194 -> 59138.983 | E11: =+E26+E152+E166+E180+E194 -> 562550.24 | F11: =+F26+F152+F166+F180+F194 -> 652642.14 | G11: =+G26+G152+G166+G180+G194 -> 437692.76 | H11: =+H26+H152+H166+H180+H194 -> 655715.37 | I11: =+I26+I152+I166+I180+I194 -> 573288.14 | J11: =+J26+J152+J166+J180+J194 -> 619227.97 | K11: =+K26+K152+K166+K180+K194 -> 466483.9
B12: % | C12: =+C11/C4 -> 0 | D12: =+D11/D4 -> 0.011519907 | E12: =+E11/E4 -> 0.096473727 | F12: =+F11/F4 -> 0.1023549 | G12: =+G11/G4 -> 0.072553663 | H12: =+H11/H4 -> 0.10720975 | I12: =+I11/I4 -> 0.09902459 | J12: =+J11/J4 -> 0.11337206 | K12: =+K11/K4 -> 0.075125035
B13: תרומה ישירה | C13: =+C4-C5-C7-C9-C11 -> 3353523.7 | D13: =+D4-D5-D7-D9-D11 -> 2042310.1 | E13: =+E4-E5-E7-E9-E11 -> 1632416.9 | F13: =+F4-F5-F7-F9-F11 -> 2278848 | G13: =+G4-G5-G7-G9-G11 -> 1638236.3 | H13: =+H4-H5-H7-H9-H11 -> 1917906.9 | I13: =+I4-I5-I7-I9-I11 -> 1758901.4 | J13: =+J4-J5-J7-J9-J11 -> 1012096.9 | K13: =+K4-K5-K7-K9-K11 -> 1689948.2
B14: רווחיות תרומה ישירה | C14: =+C13/C4 -> 0.71704087 | D14: =+D13/D4 -> 0.39782932 | E14: =+E13/E4 -> 0.27994894 | F14: =+F13/F4 -> 0.35739533 | G14: =+G13/G4 -> 0.27156045 | H14: =+H13/H4 -> 0.31357863 | I14: =+I13/I4 -> 0.30381666 | J14: =+J13/J4 -> 0.18530091 | K14: =+K13/K4 -> 0.2721582
B15: בדיקה | C15: =+C4-'הכנסות - מרכז'!I94 -> 0 | D15: =+D4-'הכנסות - מרכז'!J94 -> 0 | E15: =+E4-'הכנסות - מרכז'!K94 -> 0 | F15: =+F4-'הכנסות - מרכז'!L94 -> 0 | G15: =+G4-'הכנסות - מרכז'!M94 -> 0 | H15: =+H4-'הכנסות - מרכז'!N94 -> 0 | I15: =+I4-'הכנסות - מרכז'!O94 -> 0 | J15: =+J4-'הכנסות - מרכז'!P94 -> 0 | K15: =+K4-'הכנסות - מרכז'!Q94 -> 0
B18: כפר סבא מסכם | C18: 8.25 | D18: 9.25 | E18: 10.25 | F18: 11.25 | G18: 12.25 | H18: 1.26 | I18: 2.26 | J18: 3.26 | K18: 4.26
B19: הכנסות | C19: =+C33+C47+C61+C75+C131+C89+C103+C117 -> 3771427.3 | D19: =+D33+D47+D61+D75+D131+D89+D103+D117 -> 3190722.9 | E19: =+E33+E47+E61+E75+E131+E89+E103+E117 -> 3589999.2 | F19: =+F33+F47+F61+F75+F131+F89+F103+F117 -> 4101214.4 | G19: =+G33+G47+G61+G75+G131+G89+G103+G117 -> 3776817.8 | H19: =+H33+H47+H61+H75+H131+H89+H103+H117 -> 3768811 | I19: =+I33+I47+I61+I75+I131+I89+I103+I117 -> 3564782.3 | J19: =+J33+J47+J61+J75+J131+J89+J103+J117 -> 3355766 | K19: =+K33+K47+K61+K75+K131+K89+K103+K117 -> 3669000
B20: שכר רופאים | C20: =+C34+C48+C62+C76+C132 -> 0 | D20: =+D34+D48+D62+D76+D132+D90+D104+D118 -> 799521.8 | E20: =+E34+E48+E62+E76+E132+E90+E104+E118 -> 1036511.4 | F20: =+F34+F48+F62+F76+F132+F90+F104+F118 -> 1033474 | G20: =+G34+G48+G62+G76+G132+G90+G104+G118 -> 1218027.6 | H20: =+H34+H48+H62+H76+H132+H90+H104+H118 -> 1078842.3 | I20: =+I34+I48+I62+I76+I132+I90+I104+I118 -> 1085956.4 | J20: =+J34+J48+J62+J76+J132+J90+J104+J118 -> 1432175.1 | K20: =+K34+K48+K62+K76+K132+K90+K104+K118 -> 1315380
B21: % | C21: =+C20/C19 -> 0 | D21: =+D20/D19 -> 0.25057701 | E21: =+E20/E19 -> 0.28872189 | F21: =+F20/F19 -> 0.25199219 | G21: =+G20/G19 -> 0.32250103 | H21: =+H20/H19 -> 0.28625535 | I21: =+I20/I19 -> 0.3046347 | J21: =+J20/J19 -> 0.42678038 | K21: =+K20/K19 -> 0.35851185
B22: שכר עובדים | C22: =+C36+C50+C64+C78+C134 -> 0 | D22: =+D36+D50+D64+D78+D134+D92+D106+D120 -> 935871.2 | E22: =+E36+E50+E64+E78+E134+E92+E106+E120 -> 1055674 | F22: =+F36+F50+F64+F78+F134+F92+F106+F120 -> 967621 | G22: =+G36+G50+G64+G78+G134+G92+G106+G120 -> 1038224 | H22: =+H36+H50+H64+H78+H134+H92+H106+H120 -> 996930.52 | I22: =+I36+I50+I64+I78+I134+I92+I106+I120 -> 1032109.8 | J22: =+J36+J50+J64+J78+J134+J92+J106+J120 -> 1049914.1 | K22: =+K36+K50+K64+K78+K134+K92+K106+K120 -> 1246381.1
B23: % | C23: =+C22/C19 -> 0 | D23: =+D22/D19 -> 0.29331009 | E23: =+E22/E19 -> 0.29405968 | F23: =+F22/F19 -> 0.23593524 | G23: =+G22/G19 -> 0.27489385 | H23: =+H22/H19 -> 0.26452123 | I23: =+I22/I19 -> 0.28952956 | J23: =+J22/J19 -> 0.31286869 | K23: =+K22/K19 -> 0.33970595
B24: קבלני משנה - ספקים | C24: =+C38+C52+C66+C80+C136 -> 0 | D24: =+D38+D52+D66+D80+D136+D94+D108+D122 -> 0 | E24: =+E38+E52+E66+E80+E136 -> 53839 | F24: =+F38+F52+F66+F80+F136 -> 50246 | G24: =+G38+G52+G66+G80+G136 -> 56588.881 | H24: =+H38+H52+H66+H80+H136 -> 64173 | I24: =+I38+I52+I66+I80+I136 -> 53500 | J24: =+J38+J52+J66+J80+J136 -> 50675.424 | K24: =+K38+K52+K66+K80+K136 -> 43656.763
B25: % | C25: =+C24/C19 -> 0 | D25: =+D24/D19 -> 0 | E25: =+E24/E19 -> 0.014996939 | F25: =+F24/F19 -> 0.012251493 | G25: =+G24/G19 -> 0.014983217 | H25: =+H24/H19 -> 0.017027386 | I25: =+I24/I19 -> 0.015007929 | J25: =+J24/J19 -> 0.015101 | K25: =+K24/K19 -> 0.011898818
B26: וטמרקט | C26: =+C40+C54+C68+C82+C138 -> 0 | D26: =+D40+D54+D68+D82+D138+D96+D110+D124 -> 0 | E26: =+E40+E54+E68+E82+E138+E96+E110+E124 -> 269046 | F26: =+F40+F54+F68+F82+F138+F96+F110+F124 -> 359304 | G26: =+G40+G54+G68+G82+G138+G96+G110+G124 -> 137267 | H26: =+H40+H54+H68+H82+H138+H96+H110+H124 -> 385373 | I26: =+I40+I54+I68+I82+I138+I96+I110+I124 -> 264427.97 | J26: =+J40+J54+J68+J82+J138+J96+J110+J124 -> 330523.73 | K26: =+K40+K54+K68+K82+K138+K96+K110+K124 -> 182830.51
B27: % | C27: =+C26/C19 -> 0 | D27: =+D26/D19 -> 0 | E27: =+E26/E19 -> 0.074943193 | F27: =+F26/F19 -> 0.087609172 | G27: =+G26/G19 -> 0.036344618 | H27: =+H26/H19 -> 0.1022532 | I27: =+I26/I19 -> 0.074177873 | J27: =+J26/J19 -> 0.098494272 | K27: =+K26/K19 -> 0.049831155
B28: תרומה ישירה | C28: =+C19-C20-C22-C24-C26 -> 3771427.3 | D28: =+D19-D20-D22-D24-D26 -> 1455329.9 | E28: =+E19-E20-E22-E24-E26 -> 1174928.8 | F28: =+F19-F20-F22-F24-F26 -> 1690569.4 | G28: =+G19-G20-G22-G24-G26 -> 1326710.3 | H28: =+H19-H20-H22-H24-H26 -> 1243492.2 | I28: =+I19-I20-I22-I24-I26 -> 1128788.1 | J28: =+J19-J20-J22-J24-J26 -> 492477.64 | K28: =+K19-K20-K22-K24-K26 -> 880751.62
B29: רווחיות תרומה ישירה | C29: =+C28/C19 -> 1 | D29: =+D28/D19 -> 0.4561129 | E29: =+E28/E19 -> 0.3272783 | F29: =+F28/F19 -> 0.41221191 | G29: =+G28/G19 -> 0.35127728 | H29: =+H28/H19 -> 0.32994283 | I29: =+I28/I19 -> 0.31664993 | J29: =+J28/J19 -> 0.14675566 | K29: =+K28/K19 -> 0.24005223
B32: חירום | C32: 8.25 | D32: 9.25 | E32: 10.25 | F32: 11.25 | G32: 12.25 | H32: 1.26 | I32: 2.26 | J32: 3.26 | K32: 4.26
B33: הכנסות | C33: =+'הכנסות - מרכז'!I78 -> 1526301.7 | D33: =+'הכנסות - מרכז'!J78 -> 1456678 | E33: =+'הכנסות - מרכז'!K78 -> 1598972 | F33: =+'הכנסות - מרכז'!L78 -> 1545136.4 | G33: =+'הכנסות - מרכז'!M78 -> 1429006.8 | H33: =+'הכנסות - מרכז'!N78 -> 1568003.4 | I33: =+'הכנסות - מרכז'!O78 -> 1465456.4 | J33: =+'הכנסות - מרכז'!P78 -> 1360763.7 | K33: =+'הכנסות - מרכז'!Q78 -> 1495000
B34: שכר רופאים | D34: =+'נתוני כ"ס - חירום'!G97 -> 451826.8 | E34: =+'נתוני כ"ס - חירום'!H97 -> 423292 | F34: =+'נתוני כ"ס - חירום'!I97 -> 406374 | G34: =+'נתוני כ"ס - חירום'!J97 -> 532636 | H34: =+'נתוני כ"ס - חירום'!K97 -> 429896.04 | I34: =+'נתוני כ"ס - חירום'!L97 -> 389279.61 | J34: =+'נתוני כ"ס - חירום'!M97 -> 464606.64 | K34: =+'נתוני כ"ס - חירום'!N97 -> 545856.87
B35: % | C35: =+C34/C33 -> 0 | D35: =+D34/D33 -> 0.31017618 | E35: =+E34/E33 -> 0.26472758 | F35: =+F34/F33 -> 0.26300202 | G35: =+G34/G33 -> 0.37273161 | H35: =+H34/H33 -> 0.2741678 | I35: =+I34/I33 -> 0.2656371 | J35: =+J34/J33 -> 0.34143079 | K35: =+K34/K33 -> 0.36512165
B36: שכר עובדים | D36: =+'נתוני כ"ס - חירום'!G96 -> 432916 | E36: =+'נתוני כ"ס - חירום'!H96 -> 562197 | F36: =+'נתוני כ"ס - חירום'!I96 -> 434191 | G36: =+'נתוני כ"ס - חירום'!J96 -> 486971 | H36: =+'נתוני כ"ס - חירום'!K96 -> 418556.19 | I36: =+'נתוני כ"ס - חירום'!L96 -> 410150.89 | J36: =+'נתוני כ"ס - חירום'!M96 -> 439172.35 | K36: =+'נתוני כ"ס - חירום'!N96 -> 558265.76
B37: % | C37: =+C36/C33 -> 0 | D37: =+D36/D33 -> 0.29719403 | E37: =+E36/E33 -> 0.35159902 | F37: =+F36/F33 -> 0.28100496 | G37: =+G36/G33 -> 0.34077585 | H37: =+H36/H33 -> 0.26693577 | I37: =+I36/I33 -> 0.27987927 | J37: =+J36/J33 -> 0.32273961 | K37: =+K36/K33 -> 0.37342191
B38: קבלני משנה - ספקים
B39: % | C39: =+C38/C33 -> 0 | D39: =+D38/D33 -> 0 | E39: =+E38/E33 -> 0 | F39: =+F38/F33 -> 0 | G39: =+G38/G33 -> 0 | H39: =+H38/H33 -> 0 | I39: =+I38/I33 -> 0 | J39: =+J38/J33 -> 0 | K39: =+K38/K33 -> 0
B40: וטמרקט | E40: =+'וטרמקט ואלסמד'!J5+'וטרמקט ואלסמד'!J6 -> 232255 | F40: =+'וטרמקט ואלסמד'!K5+'וטרמקט ואלסמד'!K6 -> 302662 | G40: =+'וטרמקט ואלסמד'!L5+'וטרמקט ואלסמד'!L6 -> 82318 | H40: =+'וטרמקט ואלסמד'!M5+'וטרמקט ואלסמד'!M6 -> 298774 | I40: =+'וטרמקט ואלסמד'!N5+'וטרמקט ואלסמד'!N6 -> 200620.34 | J40: =+'וטמרקט ואלסמד 2-4.26'!L8 -> 279275.42 | K40: =+'וטמרקט ואלסמד 2-4.26'!S9 -> 126859.32
B41: % | C41: =+C40/C33 -> 0 | D41: =+D40/D33 -> 0 | E41: =+E40/E33 -> 0.1452527 | F41: =+F40/F33 -> 0.19588044 | G41: =+G40/G33 -> 0.057605045 | H41: =+H40/H33 -> 0.19054423 | I41: =+I40/I33 -> 0.13689956 | J41: =+J40/J33 -> 0.20523432 | K41: =+K40/K33 -> 0.084855734
B42: תרומה ישירה | C42: =+C33-C34-C36-C38-C40 -> 1526301.7 | D42: =+D33-D34-D36-D38-D40 -> 571935.17 | E42: =+E33-E34-E36-E38-E40 -> 381228.03 | F42: =+F33-F34-F36-F38-F40 -> 401909.44 | G42: =+G33-G34-G36-G38-G40 -> 327081.78 | H42: =+H33-H34-H36-H38-H40 -> 420777.16 | I42: =+I33-I34-I36-I38-I40 -> 465405.61 | J42: =+J33-J34-J36-J38-J40 -> 177709.32 | K42: =+K33-K34-K36-K38-K40 -> 264018.05
B43: רווחיות תרומה ישירה | C43: =+C42/C33 -> 1 | D43: =+D42/D33 -> 0.39262979 | E43: =+E42/E33 -> 0.2384207 | F43: =+F42/F33 -> 0.26011259 | G43: =+G42/G33 -> 0.22888749 | H43: =+H42/H33 -> 0.2683522 | I43: =+I42/I33 -> 0.31758406 | J43: =+J42/J33 -> 0.13059528 | K43: =+K42/K33 -> 0.1766007
B46: נוירולוגיה | C46: 8.25 | D46: 9.25 | E46: 10.25 | F46: 11.25 | G46: 12.25 | H46: 1.26 | I46: 2.26 | J46: 3.26 | K46: 4.26
B47: הכנסות | C47: =+'הכנסות - מרכז'!I79 -> 764258.47 | D47: =+'הכנסות - מרכז'!J79 -> 434802.54 | E47: =+'הכנסות - מרכז'!K79 -> 475744.07 | F47: =+'הכנסות - מרכז'!L79 -> 805726.27 | G47: =+'הכנסות - מרכז'!M79 -> 550269.49 | H47: =+'הכנסות - מרכז'!N79 -> 483768.64 | I47: =+'הכנסות - מרכז'!O79 -> 412191.26 | J47: =+'הכנסות - מרכז'!P79 -> 488269.97 | K47: =+'הכנסות - מרכז'!Q79 -> 518000
B48: שכר רופאים | D48: =+'נתוני כ"ס - נוירו '!G20 -> 121651 | E48: =+'נתוני כ"ס - נוירו '!H20+'רופאים בחשבונית'!U9 -> 109232 | F48: =+'נתוני כ"ס - נוירו '!I20+'רופאים בחשבונית'!V9 -> 122035 | G48: =+'נתוני כ"ס - נוירו '!J20+'רופאים בחשבונית'!W9 -> 131618 | H48: =+'נתוני כ"ס - נוירו '!K20+'רופאים בחשבונית'!X9 -> 134088.26 | I48: =+'נתוני כ"ס - נוירו '!L20+'רופאים בחשבונית'!Y9 -> 159341.08 | J48: =+'נתוני כ"ס - נוירו '!M20+'רופאים בחשבונית'!Z9 -> 165055.09 | K48: =+'נתוני כ"ס - נוירו '!N20+'רופאים בחשבונית'!AA9 -> 172551.43
...

Sheet הכנסות - מרכז
A1: Reporting dimension 1 | B1: January 2025 | C1: February 2025 | D1: March 2025 | E1: April 2025 | F1: May 2025 | G1: June 2025 | H1: July 2025 | I1: August 2025 | J1: September 2025 | K1: October 2025 | L1: November 2025 | M1: December 2025 | N1: January 2026
A2: Neurology | B2: 569301 | C2: 580164 | D2: 548784 | E2: 454387 | F2: 620222 | G2: 488256 | H2: 714094 | I2: 582825 | J2: 513067 | K2: 561378 | L2: 611153 | M2: 649318 | N2: 570847
A3: Surgery | B3: 693761 | C3: 647050 | D3: 717708 | E3: 680549 | F3: 663041 | G3: 503824 | H3: 748574 | I3: 662520 | J3: 523189 | K3: 659774 | L3: 754708 | M3: 731890 | N3: 773891
A4: Imaging | B4: 602179 | C4: 577282 | D4: 609174 | E4: 586706 | F4: 671100 | G4: 485303 | H4: 666377 | I4: 559190 | J4: 564709 | K4: 548550 | L4: 627537 | M4: 660803 | N4: 622191
A5: Oncology | B5: 188639 | C5: 164542 | D5: 171352 | E5: 177061 | F5: 177210 | G5: 179565 | H5: 154349 | I5: 167853 | J5: 159759 | K5: 171061 | L5: 216038 | M5: 236445 | N5: 185582
A6: Cardiology | B6: 5702 | C6: 200 | D6: -690 | E6: 0 | F6: 0 | G6: 120 | H6: 0 | I6: 0 | J6: -31 | K6: 0 | L6: 100 | M6: 39 | N6: 120
A7: Cardiology - Dan | B7: 159408 | C7: 90128 | D7: 99018 | E7: 103794 | F7: 101507 | G7: 85631 | H7: 135121 | I7: 119123 | J7: 55950 | K7: 82439 | L7: 122953 | M7: 131272 | N7: 134213
A8: Ophthalmology | B8: 21602 | C8: 10230 | D8: 9360 | E8: 10690 | F8: 20150 | G8: 10525 | H8: 14452 | I8: 7050 | J8: 14700 | K8: 15950 | L8: 15990 | M8: 16925 | N8: 5900
A9: Anesthesia | B9: 56750 | C9: 80950 | D9: 101350 | E9: 84710 | F9: 104300 | G9: 78400 | H9: 117645 | I9: 76650 | J9: 54890 | K9: 122700 | L9: 157350 | M9: 160700 | N9: 147950
A10: Management | B10: 0 | C10: 0 | D10: 1600 | E10: 1600 | F10: 0 | G10: 0 | H10: 0 | I10: -32 | J10: 0 | K10: 1600 | L10: 0 | M10: 0 | N10: 0
A11: Internal medicine | B11: 2732 | C11: 2281 | D11: 2172 | E11: 1890 | F11: 3494 | G11: 2834 | H11: 2135 | I11: 4660 | J11: 1215 | K11: 2437 | L11: -146 | M11: 1133 | N11: 4337
A12: Motzkin | B12: 0 | C12: 0 | D12: 0 | E12: 0 | F12: 0 | G12: 0 | H12: 0 | I12: 58892 | J12: 111210 | K12: 128234 | L12: 153399 | M12: 100325 | N12: 150690
B13: 0 | C13: 0 | D13: 170 | E13: 69523 | F13: 0 | G13: 0 | H13: 0 | I13: 370 | J13: 44 | K13: 0 | L13: 0 | M13: 0 | N13: 175
A14: Emergency | B14: 1625076 | C14: 1405897 | D14: 1666255 | E14: 1716943 | F14: 1846048 | G14: 1526353 | H14: 1815506 | I14: 1796376 | J14: 1717665 | K14: 1884350 | L14: 1823407 | M14: 1685095 | N14: 1845907
A15: Veterinary Center Holdings, LTD | B15: 2760 | C15: 2210 | D15: 4590 | E15: 2236 | F15: 3385 | G15: 17979 | H15: 42560 | I15: 42070 | J15: 37500 | K15: 52801 | L15: 37766 | M15: 40825 | N15: 37479
A16: Dermatology | B16: 15700 | C16: 15950 | D16: 9665 | E16: 17178 | F16: 18580 | G16: 20830 | H16: 30080 | I16: 13210 | J16: 22680 | K16: 20456 | L16: 20070 | M16: 21700 | N16: 18247
A17: Physiotherapy | B17: 0 | C17: 0 | D17: 0 | E17: 0 | F17: 0 | G17: 0 | H17: 0 | I17: 0 | J17: 0 | K17: 0 | L17: 0 | M17: 0 | N17: 0
A18: Theriogenology | B18: 2750 | C18: 1080 | D18: 1740 | E18: 3650 | F18: 0 | G18: -170 | H18: 0 | I18: 0 | J18: 0 | K18: 0 | L18: 0 | M18: 0 | N18: 0
A19: Epilepsy | B19: 0 | C19: 0 | D19: 0 | E19: 0 | F19: 250 | G19: 0 | H19: 0 | I19: 0 | J19: 0 | K19: 0 | L19: 0 | M19: 0 | N19: 0
A20: Radiotherapy | B20: 81480 | C20: 9000 | D20: 9000 | E20: 9000 | F20: 4400 | G20: 24000 | H20: 6000 | I20: 16500 | J20: 44800 | K20: 24000 | L20: 42000 | M20: 42000 | N20: 18000
A21: Cardiology - Dan 2 | B21: 23620 | C21: 53860 | D21: 77302 | E21: 64288 | F21: 78397 | G21: 37490 | H21: 77185 | I21: 78781 | J21: 54916 | K21: 48819 | L21: 70903 | M21: 78500 | N21: 82358
A22: Beer Sheva | B22: 0 | C22: 0 | D22: 0 | E22: 174921 | F22: 458319 | G22: 477634 | H22: 568629 | I22: 499759 | J22: 463592 | K22: 442972 | L22: 497645 | M22: 554152 | N22: 518222
A23: Haifa | B23: 0 | C23: 0 | D23: 0 | E23: 0 | F23: 0 | G23: 0 | H23: 0 | I23: 509799 | J23: 1025906 | K23: 1046461 | L23: 1030019 | M23: 1038804 | N23: 1188645
A24: Rehovot | B24: 0 | C24: 0 | D24: 0 | E24: 0 | F24: 0 | G24: 0 | H24: 0 | I24: 0 | J24: 691927 | K24: 1026860 | L24: 1003499 | M24: 968632 | N24: 912352
A25: Total | B25: =SUM(B2:B24) -> 4051460 | C25: =SUM(C2:C24) -> 3640824 | D25: =SUM(D2:D24) -> 4028550 | E25: =SUM(E2:E24) -> 4159126 | F25: =SUM(F2:F24) -> 4770403 | G25: =SUM(G2:G24) -> 3938574 | H25: =SUM(H2:H24) -> 5092707 | I25: =SUM(I2:I24) -> 5195596 | ... N25: =SUM(N2:N24) -> 7217106
A27: Kefar Saba | B27: =B25-SUM(B22:B24,B12) -> 4051460 | C27: =C25-SUM(C22:C24,C12) -> 3640824 | D27: =D25-SUM(D22:D24,D12) -> 4028550 | E27: =E25-SUM(E22:E24,E12) -> 3984205 | F27: =F25-SUM(F22:F24,F12) -> 4312084 | G27: =G25-SUM(G22:G24,G12) -> 3460940 | H27: =H25-SUM(H22:H24,H12) -> 4524078 | I27: =I25-SUM(I22:I24,I12) -> 4127146 | ... N27: =N25-SUM(N22:N24,N12) -> 4447197
A30: נתוני הכנסות בחלוקה אחרת
A31: חירום | B31: =+B11+B14 -> 1627808 | C31: =+C11+C14 -> 1408178 | D31: =+D11+D14 -> 1668427 | E31: =+E11+E14 -> 1718833 | F31: =+F11+F14 -> 1849542 | G31: =+G11+G14 -> 1529187 | H31: =+H11+H14 -> 1817641 | I31: =+I11+I14 -> 1801036 | ... N31: =+N11+N14 -> 1850244
A32: נוירולוגיה | B32: =+B2+B19 -> 569301 | C32: =+C2+C19 -> 580164 | D32: =+D2+D19 -> 548784 | E32: =+E2+E19 -> 454387 | F32: =+F2+F19 -> 620472 | G32: =+G2+G19 -> 488256 | H32: =+H2+H19 -> 714094 | I32: =+I2+I19 -> 582825 | ... N32: =+N2+N19 -> 570847
A33: הדמיה | B33: =+B4 -> 602179 | C33: =+C4 -> 577282 | D33: =+D4 -> 609174 | E33: =+E4 -> 586706 | F33: =+F4 -> 671100 | G33: =+G4 -> 485303 | H33: =+H4 -> 666377 | I33: =+I4 -> 559190 | ... N33: =+N4 -> 622191
A34: כירורגיה | B34: =+B3 -> 693761 | C34: =+C3 -> 647050 | D34: =+D3 -> 717708 | E34: =+E3 -> 680549 | F34: =+F3 -> 663041 | G34: =+G3 -> 503824 | H34: =+H3 -> 748574 | I34: =+I3 -> 662520 | ... N34: =+N3 -> 773891
A35: אחר | B35: =+B18+B17+B16+B15+B10+B8+B13 -> 42812 | C35: =+C18+C17+C16+C15+C10+C8+C13 -> 29470 | D35: =+D18+D17+D16+D15+D10+D8+D13 -> 27125 | E35: =+E18+E17+E16+E15+E10+E8+E13 -> 104877 | F35: =+F18+F17+F16+F15+F10+F8+F13 -> 42115 | G35: =+G18+G17+G16+G15+G10+G8+G13 -> 49164 | H35: =+H18+H17+H16+H15+H10+H8+H13 -> 87092 | I35: =+I18+I17+I16+I15+I10+I8+I13 -> 62668 | ... N35: =+N18+N17+N16+N15+N10+N8+N13 -> 61801
A36: קרדיולוגיה | B36: =+B6+B7+B21 -> 188730 | C36: =+C6+C7+C21 -> 144188 | D36: =+D6+D7+D21 -> 175630 | E36: =+E6+E7+E21 -> 168082 | F36: =+F6+F7+F21 -> 179904 | G36: =+G6+G7+G21 -> 123241 | H36: =+H6+H7+H21 -> 212306 | I36: =+I6+I7+I21 -> 197904 | ... N36: =+N6+N7+N21 -> 216691
A37: אונקולוגיה | B37: =+B5+B20 -> 270119 | C37: =+C5+C20 -> 173542 | D37: =+D5+D20 -> 180352 | E37: =+E5+E20 -> 186061 | F37: =+F5+F20 -> 181610 | G37: =+G5+G20 -> 203565 | H37: =+H5+H20 -> 160349 | I37: =+I5+I20 -> 184353 | ... N37: =+N5+N20 -> 203582
A38: הרדמה | B38: =+B9 -> 56750 | C38: =+C9 -> 80950 | D38: =+D9 -> 101350 | E38: =+E9 -> 84710 | F38: =+F9 -> 104300 | G38: =+G9 -> 78400 | H38: =+H9 -> 117645 | I38: =+I9 -> 76650 | ... N38: =+N9 -> 147950
A39: רחובות | B39: =+B24 -> 0 | C39: =+C24 -> 0 | D39: =+D24 -> 0 | E39: =+E24 -> 0 | F39: =+F24 -> 0 | G39: =+G24 -> 0 | H39: =+H24 -> 0 | I39: =+I24 -> 0 | ... N39: =+N24 -> 912352
A40: ב"ש | B40: =+B22 -> 0 | C40: =+C22 -> 0 | D40: =+D22 -> 0 | E40: =+E22 -> 174921 | F40: =+F22 -> 458319 | G40: =+G22 -> 477634 | H40: =+H22 -> 568629 | I40: =+I22 -> 499759 | ... N40: =+N22 -> 518222
A41: חיפה | B41: =+B23 -> 0 | C41: =+C23 -> 0 | D41: =+D23 -> 0 | E41: =+E23 -> 0 | F41: =+F23 -> 0 | G41: =+G23 -> 0 | H41: =+H23 -> 0 | I41: =+I23 -> 509799 | ... N41: =+N23 -> 1188645
A42: מוצקין | B42: =+B12 -> 0 | C42: =+C12 -> 0 | D42: =+D12 -> 0 | E42: =+E12 -> 0 | F42: =+F12 -> 0 | G42: =+G12 -> 0 | H42: =+H12 -> 0 | I42: =+I12 -> 58892 | ... N42: =+N12 -> 150690
B43: =SUM(B31:B42) -> 4051460 | C43: =SUM(C31:C42) -> 3640824 | D43: =SUM(D31:D42) -> 4028550 | E43: =SUM(E31:E42) -> 4159126 | F43: =SUM(F31:F42) -> 4770403 | G43: =SUM(G31:G42) -> 3938574 | H43: =SUM(H31:H42) -> 5092707 | I43: =SUM(I31:I42) -> 5195596 | ... N43: =SUM(N31:N42) -> 7217106
...

Sheet סעיפי הכנסות
A1: חשבון | B1: תיאור חשבון | C1: יתרה מוגשת
F2: ספרים | H2: פרו-וט ללא מע"מ
C3: 2024 | F3: 1-12.2025 | H3: 1-12.2025 | J3: הפרש | K3: ICOUNT | M3: הפרש בנטרול ICOUNT
A5: 8001 | B5: הכנסות - זברה | C5: -14288950 | F5: -18130415 | H5: =-SUM('הכנסות - מרכז'!B48:M48) -> -17403227 | J5: =+F5-H5 -> -727187.47 | K5: 0 | M5: =+J5-K5 -> -727187.47
A6: 8002 | B6: הכנסות - כירורגיה | C6: -6936475.5 | F6: -7447978.2 | H6: =-SUM('הכנסות - מרכז'!B51:M51) -> -6768294.9 | J6: =+F6-H6 -> -679683.33 | K6: =-SUM('הכנסות - מרכז'!B67:M67) -> -46600 | M6: =+J6-K6 -> -633083.33
A7: 8003 | B7: הכנסות - וטנוירו | C7: -6452402.4 | F7: -7587444.5 | H7: =-SUM('הכנסות - מרכז'!B49:M49) -> -5841694.1 | J7: =+F7-H7 -> -1745750.4 | K7: =-SUM('הכנסות - מרכז'!B65:M65) -> -1048140.7 | M7: =+J7-K7 -> -697609.72
A8: 8004 | B8: הכנסות - הדמיה | C8: -6170793.4 | F8: -6793605 | H8: =-SUM('הכנסות - מרכז'!B50:M50) -> -6066872.9 | J8: =+F8-H8 -> -726732.15 | K8: =-SUM('הכנסות - מרכז'!B66:M66) -> -39700.85 | M8: =+J8-K8 -> -687031.3
A9: 8005 | B9: הכנסות - מרכז | C9: -1297903.1 | F9: -45468.64 | M9: =+J9-K9 -> 0
A10: 8006 | B10: הכנסות קרדיולוגיה יעל גולני | C10: -94384.61 | F10: -4703.39 | H10: =-SUM('הכנסות - מרכז'!B53:M53) -> -1725292.4 | J10: =+F10+F11-H10 -> -68831.367 | M10: =+J10-K10 -> -68831.367
A11: 8007 | B11: הכנסות קרדיולוגיה דני אוהד | C11: -637640.18 | F11: -1789420.4
A12: 8008 | B12: הכנסות אונקולוגיה | C12: -861125.64 | F12: -2181507.6 | H12: =-SUM('הכנסות - מרכז'!B54:M54) -> -2098350.8 | J12: =+F12-H12 -> -83156.783 | M12: =+J12-K12 -> -83156.783
A13: 8009 | B13: הכנסות דרמטולוגיה | C13: -74303.43 | F13: -198557.62 | H13: =-SUM('הכנסות - מרכז'!B52:M52,'הכנסות - מרכז'!B55:M55) -> -1661631.4 | J13: =+F13+F9+F14+F15+F16-H13 -> 1259618.7 | K13: =-SUM('הכנסות - מרכז'!B68:M68) -> -62735.81 | M13: =+J13-K13 -> 1322354.5
A14: 8010 | B14: הכנסות אופטמולוגיה | C14: -40596.58 | F14: -149706.78
A15: 8011 | B15: הכנסות סמדר טל | C15: -11033.33 | F15: -6923.73
A16: 8012 | B16: הכנסות אפילפסיה | C16: -2820.52 | F16: -1355.93
A17: 8000 | B17: הכנסות - רשת | C17: -113470.08 | F17: 0
C19: =SUM(C5:C18) -> -36981899 | F19: =SUM(F5:F18) -> -44337086 | H19: =SUM(H5:H17) -> -41565364 | J19: =SUM(J5:J16) -> -2771722.8 | K19: =SUM(K5:K16) -> -1197177.3 | M19: =SUM(M5:M16) -> -1574545.5 | N19: יתרת הפרש - קיימת הכנסה בספרים ולא בפרווט
H20: =SUM('הכנסות - מרכז'!B48:M55)+H19 -> 0

Sheet וטרמקט ואלסמד
B1: הדמיה | C1: נוירולוגיה | D1: כירורגיה | E1: חירום | F1: חירום מעבדה חיצוני | I1: כפר סבא | J1: 45931 | K1: 45962 | L1: 45992 | M1: 46023 | N1: 46054 | O1: סה"כ
A2: 45931 | B2: 5609 | C2: 25750 | D2: 5432 | E2: 229004 | F2: 3251 | I2: הדמיה | J2: 5609 | K2: 5777 | L2: 3228 | M2: 7894 | N2: =+'וטמרקט ואלסמד 2-4.26'!C11 -> 19785.593 | O2: 22580
A3: 45962 | B3: 5777 | C3: 15569 | D3: 35296 | E3: 296981 | F3: 5681 | I3: נוירולוגיה | J3: 25750 | K3: 15569 | L3: 26108 | M3: 16373 | N3: =+'וטמרקט ואלסמד 2-4.26'!C9 -> 23022.034 | O3: 83800
A4: 45992 | B4: 3228 | C4: 26108 | D4: 25613 | E4: 78689 | F4: 3629 | I4: כירורגיה | J4: 5432 | K4: 35296 | L4: 25613 | M4: 62332 | N4: =+'וטמרקט ואלסמד 2-4.26'!C10 -> 21000 | O4: 128673
A5: 46023 | B5: 7894 | C5: 16373 | D5: 62332 | E5: 298309 | F5: 465 | I5: חירום | J5: 229004 | K5: 296981 | L5: 78689 | M5: 298309 | N5: =+'וטמרקט ואלסמד 2-4.26'!C8 -> 200620.34 | O5: 902983
A6: סהכ | B6: 22580 | C6: 83800 | D6: 128673 | E6: 902983 | F6: 13026 | I6: חירום מעבדה חיצוני | J6: 3251 | K6: 5681 | L6: 3629 | M6: 465 | N6: 0 | O6: 13026
I12: באר שבע
K13: 45930 | L13: 45961 | M13: 45991 | N13: 46022 | O13: 46053 | P13: 46081
J14: כולל מע"מ | K14: 59150 | L14: 100783 | M14: 72106 | N14: 98946 | O14: 72106
J15: ללא מע"מ | K15: =+K14/1.18 -> 50127.119 | L15: =+L14/1.18 -> 85409.322 | M15: =+M14/1.18 -> 61106.78 | N15: =+N14/1.18 -> 83852.542 | O15: =+O14/1.18 -> 61106.78 | P15: =+'וטמרקט ואלסמד 2-4.26'!C14 -> 77523.729
I19: מוצקין
K41: 45930 | L41: 45961 | M41: 45991 | N41: 46022 | O41: 46053 | P41: 46081
J42: כולל מע"מ | K42: 10634 | L42: 11429 | M42: 14076 | N42: 17675 | O42: 11429
J43: ללא מע"מ | K43: =+K42/1.18 -> 9011.8644 | L43: =+L42/1.18 -> 9685.5932 | M43: =+M42/1.18 -> 11928.814 | N43: =+N42/1.18 -> 14978.814 | O43: =+O42/1.18 -> 9685.5932 | P43: =+'וטמרקט ואלסמד 2-4.26'!C13 -> 18967.797
I49: יש לי את התשלומים שבוצעו בינוא, בהנחה שהבנקים מותאמים בכלל החברות:
I50: מספר חברה | J50: שם חברה | K50: מספר חשבון | L50: שם חשבון | M50: יתרה | O50: מטבע | P50: שנה
I51: 1 | J51: מרכז וטרינרי החזקות בע"מ | K51: 50032 | L51: וטמרקט בע"מ | M51: 267256.82 | O51: NIS | P51: 2026 | Q51: =+M51/1.18 -> 226488.83
I52: 2 | J52: מי ווט בע"מ | K52: 50032 | L52: וטמרקט בע"מ | M52: 133382 | O52: NIS | P52: 2026 | Q52: =+M52/1.18 -> 113035.59
I53: 3 | J53: ווט מוצקין בע"מ | K53: 50032 | L53: וטמרקט בע"מ | M53: 11429 | O53: NIS | P53: 2026 | Q53: =+M53/1.18 -> 9685.5932
I54: 4 | J54: מרכז וטרינרי ברנע בע"מ | K54: 50032 | L54: וטמרקט בע"מ | M54: 72106 | O54: NIS | P54: 2026 | Q54: =+M54/1.18 -> 61106.78
I55: 5 | J55: מרכז וטרינרי רחובות בע"מ | K55: 50032 | L55: וטמרקט בע"מ | M55: 102087 | O55: NIS | P55: 2026 | Q55: =+M55/1.18 -> 86514.407
I60: חיפה
L61: 45930 | M61: 45961 | N61: 45991 | O61: 46022 | P61: 46053 | Q61: 46081
K62: כולל מע"מ | L62: 143412 | M62: 133382 | N62: =154448+3422 -> 157870 | O62: 135835 | P62: 133382
K63: ללא מע"מ | L63: =+L62/1.18 -> 121535.59 | M63: =+M62/1.18 -> 113035.59 | N63: =+N62/1.18 -> 133788.14 | O63: =+O62/1.18 -> 115114.41 | P63: =+P62/1.18 -> 113035.59 | Q63: =+'וטמרקט ואלסמד 2-4.26'!C12 -> 123813.56
I80: רחובות
P82: הערכה
K83: 45869 | L83: 45900 | M83: 45930 | N83: 45961 | O83: 45991 | P83: 46022 | Q83: 46053 | R83: 46081
J84: כולל מע"מ | K84: 102254 | L84: 90889 | M84: 114261 | N84: 100741 | O84: 102087 | P84: =AVERAGE(K84:O84) -> 102046.4 | Q84: 102087
J85: ללא מע"מ | K85: =+K84/1.18 -> 86655.932 | L85: =+L84/1.18 -> 77024.576 | M85: =+M84/1.18 -> 96831.356 | N85: =+N84/1.18 -> 85373.729 | O85: =+O84/1.18 -> 86514.407 | P85: =+P84/1.18 -> 86480 | Q85: =+Q84/1.18 -> 86514.407 | R85: =+'וטמרקט ואלסמד 2-4.26'!C15 -> 88555.085
B115: אלסמד
A120: 4010 | B120: 400
B121: יתרת פתיחה | Q121: 80244.95
C122: 13119 | D122: 22841 | E122: 9997 | G122: 2001 | H122: 45664 | I122: 45664 | J122: 31622 | L122: אלסמד בעמ | O122: 46899.95 | Q122: 33345
C123: 15978 | D123: 28296 | E123: 158 | F123: 18 | G123: 8331 | H123: 45708 | I123: 45708 | J123: 0 | K123: 32 | L123: אלסמד בע"מ | P123: 50399.97 | Q123: 83744.97 | R123: =+P123/1.18 -> 42711.839
C124: 15991 | D124: 28332 | E124: 158 | F124: 18 | G124: 8431 | H124: 45708 | I124: 45708 | J124: 0 | K124: 31 | L124: אלסמד בע"מ | P124: 16815 | Q124: 100559.97 | R124: =+P124/1.18 -> 14250
C125: 15893 | D125: 28128 | E125: 9997 | G125: 2001 | H125: 45718 | I125: 45718 | J125: 95298 | L125: אלסמד בעמ | O125: 50399.97 | Q125: 50160 | R125: =+P125/1.18 -> 0
C126: 15894 | D126: 28129 | E126: 9997 | G126: 2001 | H126: 45718 | I126: 45718 | J126: 95299 | L126: אלסמד בעמ | O126: 16815 | Q126: 33345 | R126: =+P126/1.18 -> 0
C127: 17148 | D127: 30170 | E127: 167 | F127: 18 | G127: 8431 | H127: 45735 | I127: 45735 | J127: 0 | K127: 55 | L127: אלסמד בע"מ | P127: 16697 | Q127: 50042 | R127: =+P127/1.18 -> 14150
C128: 17181 | D128: 30255 | E128: 167 | F128: 18 | G128: 8331 | H128: 45735 | I128: 45735 | J128: 0 | K128: 56 | L128: אלסמד בע"מ | P128: 52359.96 | Q128: 102401.96 | R128: =+P128/1.18 -> 44372.847
...

Sheet וטמרקט ואלסמד 2-4.26
C4: 2.2026 | J4: 3.2026 | O4: 4.2026
B6: ללא מע"מ | C6: ללא מע"מ | D6: כולל מע"מ | E6: כולל מע"מ | I6: כולל מע"מ | J6: כולל מע"מ | K6: ללא מעמ | L6: ללא מעמ
B7: אלסמד | C7: וטמרקט | D7: אלסמד | E7: וטמרקט | I7: אלסמד | J7: וטמרקט | K7: אלסמד | L7: וטמרקט | P7: כולל מע"מ | R7: ללא מעמ | S7: ללא מעמ
C8: =+E8/1.18 -> 200620.34 | E8: 236732 | F8: כ"ס- חירום | H8: כ"ס- חירום | J8: 329545 | K8: =+I8/1.18 -> 0 | L8: =+J8/1.18 -> 279275.42 | P8: אלסמד | Q8: וטמרקט | R8: אלסמד | S8: וטמרקט
A9: הערכה כי טרם התקבל נתון | B9: 43000 | C9: =+E9/1.18 -> 23022.034 | E9: 27166 | F9: כ"ס- נוירולוגיה | H9: כ"ס- נוירולוגיה | I9: 44870 | J9: 10955 | K9: =+I9/1.18 -> 38025.424 | L9: =+J9/1.18 -> 9283.8983 | O9: כ"ס- חירום | Q9: 149694 | R9: =+P9/1.18 -> 0 | S9: =+Q9/1.18 -> 126859.32
C10: =+E10/1.18 -> 21000 | E10: 24780 | F10: כ"ס- כירורגיה | H10: כ"ס- כירורגיה | J10: 47454 | K10: =+I10/1.18 -> 0 | L10: =+J10/1.18 -> 40215.254 | O10: כ"ס- נוירולוגיה | P10: 40599.98 | Q10: 20162 | R10: =+P10/1.18 -> 34406.763 | S10: =+Q10/1.18 -> 17086.441
B11: =+D11/1.18 -> 10500 | C11: =+E11/1.18 -> 19785.593 | D11: 12390 | E11: 23347 | F11: כ"ס- הדמיה | H11: כ"ס- הדמיה | I11: 14927 | J11: 2064 | K11: =+I11/1.18 -> 12650 | L11: =+J11/1.18 -> 1749.1525 | O11: כ"ס- כירורגיה | Q11: 38809 | R11: =+P11/1.18 -> 0 | S11: =+Q11/1.18 -> 32888.983
C12: =+E12/1.18 -> 123813.56 | E12: 146100 | F12: חיפה | H12: חיפה | J12: 169061 | K12: =+I12/1.18 -> 0 | L12: =+J12/1.18 -> 143272.03 | O12: כ"ס- הדמיה | P12: 10915 | Q12: 7075 | R12: =+P12/1.18 -> 9250 | S12: =+Q12/1.18 -> 5995.7627
C13: =+E13/1.18 -> 18967.797 | E13: 22382 | F13: מוצקין | H13: מוצקין | J13: 15685 | K13: =+I13/1.18 -> 0 | L13: =+J13/1.18 -> 13292.373 | O13: חיפה | Q13: 113859 | R13: =+P13/1.18 -> 0 | S13: =+Q13/1.18 -> 96490.678
C14: =+E14/1.18 -> 77523.729 | E14: 91478 | F14: ב"ש | H14: ב"ש | J14: 69283 | K14: =+I14/1.18 -> 0 | L14: =+J14/1.18 -> 58714.407 | O14: מוצקין | Q14: 7290 | R14: =+P14/1.18 -> 0 | S14: =+Q14/1.18 -> 6177.9661
C15: =+E15/1.18 -> 88555.085 | E15: 104495 | F15: רחובות | H15: רחובות | J15: 86642 | K15: =+I15/1.18 -> 0 | L15: =+J15/1.18 -> 73425.424 | O15: ב"ש | Q15: 126920 | R15: =+P15/1.18 -> 0 | S15: =+Q15/1.18 -> 107559.32
B16: =SUM(B8:B15) -> 53500 | C16: =SUM(C8:C15) -> 573288.14 | D16: =SUM(D8:D15) -> 12390 | E16: =SUM(E8:E15) -> 676480 | I16: =SUM(I8:I15) -> 59797 | J16: =SUM(J8:J15) -> 730689 | K16: =SUM(K8:K15) -> 50675.424 | L16: =SUM(L8:L15) -> 619227.97 | O16: רחובות | Q16: 86642 | R16: =+P16/1.18 -> 0 | S16: =+Q16/1.18 -> 73425.424
P17: 51514.98 | Q17: 550451 | R17: =SUM(R9:R16) -> 43656.763 | S17: =SUM(S9:S16) -> 466483.9

Sheet רופאים בחשבונית
A1: קבלני משנה
T3: 45930 | U3: 45961 | V3: 45991 | W3: 46022 | X3: 46053 | Y3: 46081 | Z3: 46112 | AA3: 46142
S4: אונקולוגיה - אונקופט | T4: =+T83 -> 152855.93 | U4: =+U83 -> 142355.93 | V4: =+V83 -> 160729.66 | W4: =+W83 -> 180990.68 | X4: =+AF16 -> 142633.9 | Y4: =+AF36 -> 156339.31 | Z4: =+AE61 -> 125261.86 | AA4: =+AE80 -> 192828.81
S5: קרדיולוגיה - תשומת לב | T5: =+T84 -> 76381.83 | U5: =+U84 -> 39178.37 | V5: =+V84 -> 44536.1 | W5: =+W84 -> 75014.95 | X5: =+AF17 -> 75466.102 | Y5: =+AF37 -> 64162.28 | Z5: =+AE62 -> 46646.127 | AA5: =+AE81 -> 67181.356
S6: אחר - אלעד פרי | T6: =+T85 -> 8093.22 | U6: =+U85 -> 15843.22 | V6: =+V85 -> 13389.83 | W6: =+W85 -> 12838.98 | X6: =+AF18 -> 13008.475 | Y6: =+AF38 -> 12923.729 | Z6: =+AE63 -> 12161.017 | AA6: =+AE82 -> 14699.153
A7: באר שבע | S7: אחר - אורן פאר | T7: =+T86 -> 5720.34 | U7: =+U86 -> 10389.83 | V7: =+V86 -> 12203.39 | W7: =+W86 -> 11661.02 | X7: =+AF19 -> 4067.7966 | Y7: =+AF39 -> 13152.542 | Z7: =+AE64 -> 11216.949 | AA7: =+AE83 -> 13203.39
S8: כירורגיה - רותם יוסף | T8: =+T87 -> 0 | U8: =+U87 -> 0 | V8: =+V87 -> 0 | W8: 0 | X8: =+AF20 -> 7953.3898 | Y8: =+AF40 -> 11512.712 | Z8: 0 | AA8: 0
S9: נוירו - סרוגו איתי - בחשבונית | T9: 27000 | U9: 27000 | V9: 27000 | W9: 27000 | X9: 27000 | Y9: 27000 | Z9: 27000 | AA9: 27000
A10: וטרינרים חיצוניים | B10: 85109 | C10: 840 | S10: רחובות | T10: =+S127 -> 47838.983 | U10: =+T127 -> 38148.305 | V10: =+U127 -> 40618.644 | W10: =+V127 -> 43029.661 | X10: =+AF28 -> 43902.542 | Y10: =+AF46 -> 40843.22 | Z10: =+AE71 -> 41860.169 | AA10: =+AA90 -> 47957.627
C11: יתרת פתיחה | Q11: 0 | S11: חיפה | T11: =+S232 -> 102499.15 | U11: =+T232 -> 92387.28 | V11: =+U232 -> 68870.34 | W11: =+V232 -> 97279.66 | X11: =+AF21+AF22+AF23+AF24+AF25+AF26+AF27 -> 25762.712 | Y11: =+AF41+AF42+AF43+AF44+AF45 -> 50449.153 | Z11: =+AE65+AE66+AE67+AE68+AE69+AE70 -> 58826.271 | AA11: =+AA84 -> 46014.407
D12: 239930 | E12: 573404 | F12: 679 | G12: הוצ | H12: 520103 | I12: 45663 | J12: 45663 | K12: 0 | L12: 10934 | M12: שירותי וטרינריה | O12: 932.2 | Q12: -932.2 | S12: באר שבע | T12: =+O40+O41 -> 17918.58 | U12: =+O42+O43 -> 18691.53 | V12: =+O44+O45 -> 17853.82 | W12: =+O46+O47+O48 -> 25054.66 | X12: =+AF29+AF30+AF31 -> 22800 | Y12: =+AF47+AF48+AF49+AF50 -> 19447.652 | Z12: =+AE72+AE73+AE74+AE75 -> 27955.127 | AA12: =+AA92 -> 18249.153
D13: 239903 | E13: 573310 | F13: 679 | G13: הוצ | H13: 52119 | I13: 45666 | J13: 45666 | K13: 0 | L13: 101044 | M13: 12.24 שירותי וטרינריה | O13: 7083.9 | Q13: -8016.1 | S13: מוצקין | T13: 0 | U13: 0 | V13: 0 | W13: 0 | X13: 0 | Y13: 0 | Z13: 0 | AA13: 0
D14: 244507 | E14: 584548 | F14: 692 | G14: הוצ | H14: 52020 | I14: 45667 | J14: 45667 | K14: 0 | L14: 962 | M14: שכ"ט | O14: 10169.49 | Q14: -18185.59
D15: 244509 | E15: 584554 | F15: 692 | G15: הוצ | H15: 52020 | I15: 45667 | J15: 45667 | K15: 0 | L15: 963 | M15: שכ"ט | O15: 1818.64 | Q15: -20004.23 | AB15: אתר | AC15: רופא עצמאי | AD15: ינואר 2026 | AE15: סכום לתשלום | AF15: ללא מע"מ | AG15: סטאטוס
D16: 244506 | E16: 584545 | F16: 692 | G16: הוצ | H16: 52020 | I16: 45698 | J16: 45698 | K16: 0 | L16: 964 | M16: שכ"ט | O16: 10169.49 | Q16: -30173.72 | AB16: מרכז וטרינרי החזקות בע"מ | AC16: אונקופט | AD16: אושר ע"י כספים | AE16: 168308 | AF16: =+AE16/1.18 -> 142633.9 | AG16: נחתם בבנק | AH16: אונוקולוגיה
D17: 244508 | E17: 584551 | F17: 692 | G17: הוצ | H17: 52020 | I17: 45698 | J17: 45698 | K17: 0 | L17: 965 | M17: שכ"ט | O17: 1470.34 | Q17: -31644.06 | AC17: תשומת לב | AD17: אושר ע"י כספים | AE17: 89050 | AF17: =+AE17/1.18 -> 75466.102 | AG17: נחתם בבנק | AH17: קרדיולוגיה
D18: 244510 | E18: 584557 | F18: 692 | G18: הוצ | H18: 52020 | I18: 45698 | J18: 45698 | K18: 0 | L18: 966 | M18: שכ"ט | O18: 10169.49 | Q18: -41813.55 | AC18: אלעד פרי | AD18: אושר ע"י כספים | AE18: 15350 | AF18: =+AE18/1.18 -> 13008.475 | AH18: דרמטולוגיה - אחר
D19: 249828 | E19: 596826 | F19: 712 | G19: הוצ | H19: 52119 | I19: 45698 | J19: 45698 | K19: 0 | L19: 1107 | M19: ד"ר יובל ריטוב | O19: 6415.25 | Q19: -48228.8 | AC19: אורן פאר | AD19: אושר ע"י כספים | AE19: 4800 | AF19: =+AE19/1.18 -> 4067.7966 | AH19: עיניים - אחר
D20: 244539 | E20: 584641 | F20: 693 | G20: הוצ | H20: 52018 | I20: 45719 | J20: 45719 | K20: 0 | L20: 991 | M20: ייעוץ אורטופדי | O20: 593.22 | Q20: -48822.02 | AC20: רותם יוסף | AD20: אושר ע"י כספים | AE20: 9385 | AF20: =+AE20/1.18 -> 7953.3898 | AG20: נחתם בבנק | AH20: כירורגיה
D21: 244505 | E21: 584542 | F21: 692 | G21: הוצ | H21: 52020 | I21: 45726 | J21: 45726 | K21: 0 | L21: 971 | M21: שכ"ט | O21: 1360.17 | Q21: -50182.19 | AB21: מי ווט בע"מ | AC21: ידין ישורון | AF21: =+AE21/1.18 -> 0 | AG21: לא עבר אישור של כספים
D22: 245794 | E22: 587754 | F22: 702 | H22: 52020 | I22: 45726 | J22: 45726 | K22: 0 | L22: 972 | M22: שכ"ט | O22: 12000 | Q22: -62182.19 | AC22: שירלי פורמנסקי | AF22: =+AE22/1.18 -> 0 | AI22: הסבר לקיטון בינואר בחיפה
D23: 244540 | E23: 584644 | F23: 693 | G23: הוצ | H23: 52119 | I23: 45727 | J23: 45727 | K23: 0 | L23: 1173 | M23: 2.25 שירות וטרינרי | O23: 7410.17 | Q23: -69592.36 | AC23: חני רצקין | AE23: 13800 | AF23: =+AE23/1.18 -> 11694.915 | AI23: ידן ישורון- לא עבד בחודש ינואר, יש אולי יום אחד שעבד אך עדיין לא שלח חשבונית ולכן לא הועבר.
D24: 245785 | E24: 587726 | F24: 702 | G24: הוצ | H24: 52119 | I24: 45754 | J24: 45754 | K24: 0 | L24: 1251 | M24: 3.25 שירות | O24: 7929.66 | Q24: -77522.02 | AC24: מאור גולדמן | AE24: 7200 | AF24: =+AE24/1.18 -> 6101.6949 | AI24: שירלי פומרנסקי- גם כן עבדה ימים בודדים בינואר, שלחה אתמול פירוט אך עדיין לא הסתכלתי על מה ששלחה.
D25: 245795 | E25: 587755 | F25: 702 | H25: 52020 | I25: 45757 | J25: 45757 | K25: 0 | L25: 973 | M25: שכ"ט | O25: 2145 | Q25: -79667.02 | AC25: אורן פאר | AE25: 4850 | AF25: =+AE25/1.18 -> 4110.1695 | AI25: נטלי סבירסקי- מגיעה לעיתים רחוקות מאוד ולכן לא תיראי העברות בתדירות חודשית, רק בחודשים שתגיע אלינו.
D26: 245765 | E26: 587666 | F26: 702 | G26: הוצ | H26: 52119 | I26: 45767 | J26: 45767 | K26: 0 | L26: 1282 | M26: שי לחג | O26: 254.24 | Q26: -79921.26 | AC26: אלעד פרי | AE26: 4550 | AF26: =+AE26/1.18 -> 3855.9322
D27: 249424 | E27: 596041 | F27: 707 | G27: הוצ | H27: 52119 | I27: 45782 | J27: 45782 | K27: 0 | L27: 1320 | M27: 5.25 שירות | O27: 7077.97 | Q27: -86999.23 | AC27: נטלי סבירסקי - רופאה מרדימה | AF27: =+AE27/1.18 -> 0
D28: 249519 | E28: 596171 | F28: 707 | G28: הוצ | H28: 520103 | I28: 45783 | J28: 45783 | K28: 0 | L28: 1127 | M28: שירותי וטרינריה | O28: 897.46 | Q28: -87896.69 | AB28: מרכז וטרינרי רחובות בע"מ | AC28: נדב מרחבי | AD28: אושר ע"י כספים | AE28: 51805 | AF28: =+AE28/1.18 -> 43902.542
D29: 249820 | E29: 596793 | F29: 712 | G29: הוצ | H29: 52020 | I29: 45787 | J29: 45787 | K29: 0 | L29: 974 | M29: שכ"ט ש'ק 483 | O29: 10169.49 | Q29: -98066.18 | AB29: מרכז וטרינרי ברנע בע"מ | AC29: יובל ריטוב | AD29: אושר ע"י כספים | AE29: 7304.5 | AF29: =+AE29/1.18 -> 6190.2542 | AG29: נחתם בבנק
D30: 249821 | E30: 596796 | F30: 712 | G30: הוצ | H30: 52020 | I30: 45787 | J30: 45787 | K30: 0 | L30: 975 | M30: שכ"ט ש'ק 484 | O30: 1746.61 | Q30: -99812.79 | AC30: אייל אברם | AD30: אושר ע"י כספים | AE30: 14402 | AF30: =+AE30/1.18 -> 12205.085 | AG30: נחתם בבנק
D31: 249827 | E31: 596823 | F31: 712 | G31: הוצ | H31: 52119 | I31: 45813 | J31: 45813 | K31: 0 | L31: 1393 | M31: ד"ר יובל ריטוב | O31: 9360.17 | Q31: -109172.96 | AC31: איתן ברנע | AD31: אושר ע"י כספים | AE31: 5197.5 | AF31: =+AE31/1.18 -> 4404.661 | AG31: נחתם בבנק
D32: 249819 | E32: 596790 | F32: 712 | G32: הוצ | H32: 52020 | I32: 45823 | J32: 45823 | K32: 0 | L32: 981 | M32: שכ"ט ש'ק 386 | O32: 723.73 | Q32: -109896.69
D33: 249822 | E33: 596808 | F33: 712 | G33: הוצ | H33: 52020 | I33: 45823 | J33: 45823 | K33: 0 | L33: 976 | M33: שכ"ט ש'ק 485 | O33: 10169.49 | Q33: -120066.18
D34: 252181 | E34: 601404 | F34: 747 | G34: הוצ | H34: 52119 | I34: 45845 | J34: 45845 | K34: 0 | L34: 1501 | M34: ד"ר יובל ריטוב- וטרינר עד הבית | O34: 6105.93 | Q34: -126172.11
D35: 250117 | E35: 597259 | F35: 717 | H35: 52020 | I35: 45848 | J35: 45848 | K35: 0 | L35: 982 | M35: ד"ר אייל אברם | O35: 12000 | Q35: -138172.11 | AB35: אתר | AC35: רופא עצמאי | AD35: 46054 | AE35: סכום לתשלום | AF35: ללא מע"מ | AG35: סטאטוס
D36: 250119 | E36: 597263 | F36: 717 | H36: 52020 | I36: 45848 | J36: 45848 | K36: 0 | L36: 983 | M36: ד"ר אייל אברם | O36: 1875 | Q36: -140047.11 | AB36: מרכז וטרינרי החזקות בע"מ | AC36: אונקופט | AD36: אושר ע"י כספים | AE36: 184480.38 | AF36: =+AE36/1.18 -> 156339.31 | AG36: טרם עלה לבנק
D37: 250271 | E37: 597567 | F37: 719 | G37: הוצ | H37: 52036 | I37: 45854 | J37: 45854 | K37: 0 | L37: 866 | M37: מרפאה וטרינרית ברנע | O37: 9853.39 | Q37: -149900.5 | AC37: תשומת לב | AD37: אושר ע"י כספים | AE37: 75711.49 | AF37: =+AE37/1.18 -> 64162.28 | AG37: נחתם בבנק
D38: 250283 | E38: 597601 | F38: 719 | G38: הוצ | H38: 52020 | I38: 45876 | J38: 45876 | K38: 0 | L38: 984 | M38: ד"ר איל אברם | O38: 11700.21 | Q38: -161600.71 | AC38: אלעד פרי | AD38: אושר ע"י כספים | AE38: 15250 | AF38: =+AE38/1.18 -> 12923.729 | AG38: נחתם בבנק
D39: 250291 | E39: 597631 | F39: 719 | G39: הוצ | H39: 52119 | I39: 45877 | J39: 45877 | K39: 0 | L39: 1586 | M39: ד"ר יובל ריטוב 7.25 | O39: 6355.93 | Q39: -167956.64 | AC39: אורן פאר | AD39: אושר ע"י כספים | AE39: 15520 | AF39: =+AE39/1.18 -> 13152.542 | AG39: נחתם בבנק
D40: 250398 | E40: 597830 | F40: 725 | G40: הוצ | H40: 52020 | I40: 45907 | J40: 45907 | K40: 0 | L40: 985 | M40: ד"ר אייל אברם | O40: 11815.19 | Q40: -179771.83 | AC40: רותם יוסף | AD40: אושר ע"י כספים | AE40: 13585 | AF40: =+AE40/1.18 -> 11512.712 | AG40: נחתם בבנק
D41: 250396 | E41: 597824 | F41: 725 | G41: הוצ | H41: 52119 | I41: 45908 | J41: 45908 | K41: 0 | L41: 1660 | M41: ד"ר יובל ריטוב- | O41: 6103.39 | Q41: -185875.22 | AB41: מי ווט בע"מ | AC41: ידין ישורון | AE41: 31785 | AF41: =+AE41/1.18 -> 26936.441 | AG41: לא התקבל החודש
...

Sheet נתוני רחובות
A1: מספר עובד חדש | B1: שם העובד | C1: 8.25 | D1: 9.25 | E1: 10.25 | F1: 11.25 | G1: 12.25 | H1: 1.26 | I1: 2.26 | J1: 3.26 | K1: 4.26
A2: 26 | B2: 0002 - אריאלי שרון | C2: =VLOOKUP(B2,[1]השוואה!$A$2:$G$56,2,FALSE) -> 18212.31 | D2: =VLOOKUP(B2,[1]השוואה!$A$2:$G$56,3,FALSE) -> 17869.13 | E2: =VLOOKUP(B2,[1]השוואה!$A$2:$G$56,4,FALSE) -> 17744.38 | F2: =VLOOKUP(B2,[1]השוואה!$A$2:$G$56,5,FALSE) -> 15471.92 | G2: =VLOOKUP(B2,[1]השוואה!$A$2:$G$56,6,FALSE) -> 16429.71 | H2: =VLOOKUP(B2,[1]השוואה!$A$2:$G$56,7,FALSE) -> 16425.54 | I2: =VLOOKUP(A2,[2]השוואה!$A$2:$H$56,8,FALSE) -> 17467.37 | J2: =VLOOKUP(A2,[3]השוואה!$A$2:$J$57,10,FALSE) -> 15055.62 | K2: 20357.54
A3: 42 | B3: 0004 - ארוגטי עירית | C3: =VLOOKUP(B3,[1]השוואה!$A$2:$G$56,2,FALSE) -> 23408.7 | D3: =VLOOKUP(B3,[1]השוואה!$A$2:$G$56,3,FALSE) -> 24056.11 | E3: =VLOOKUP(B3,[1]השוואה!$A$2:$G$56,4,FALSE) -> 24101.48 | F3: =VLOOKUP(B3,[1]השוואה!$A$2:$G$56,5,FALSE) -> 21703.96 | G3: =VLOOKUP(B3,[1]השוואה!$A$2:$G$56,6,FALSE) -> 21952.52 | H3: =VLOOKUP(B3,[1]השוואה!$A$2:$G$56,7,FALSE) -> 22436.2 | I3: =VLOOKUP(A3,[2]השוואה!$A$2:$H$56,8,FALSE) -> 20857.01 | J3: =VLOOKUP(A3,[3]השוואה!$A$2:$J$57,10,FALSE) -> 20913.17 | K3: 22233.92
A4: 59 | B4: 0005 - הראל מיכל | C4: =VLOOKUP(B4,[1]השוואה!$A$2:$G$56,2,FALSE) -> 23191.37 | D4: =VLOOKUP(B4,[1]השוואה!$A$2:$G$56,3,FALSE) -> 1220.52 | E4: =VLOOKUP(B4,[1]השוואה!$A$2:$G$56,4,FALSE) -> 1220.52 | F4: =VLOOKUP(B4,[1]השוואה!$A$2:$G$56,5,FALSE) -> 1220.52 | G4: =VLOOKUP(B4,[1]השוואה!$A$2:$G$56,6,FALSE) -> 29894.55 | H4: =VLOOKUP(B4,[1]השוואה!$A$2:$G$56,7,FALSE) -> 0 | I4: =VLOOKUP(A4,[2]השוואה!$A$2:$H$56,8,FALSE) -> 0 | J4: =VLOOKUP(A4,[3]השוואה!$A$2:$J$57,10,FALSE) -> 52650 | K4: 0
A5: 0 | B5: 0007 - דבורקין אן | C5: =VLOOKUP(B5,[1]השוואה!$A$2:$G$56,2,FALSE) -> 24022.37 | D5: =VLOOKUP(B5,[1]השוואה!$A$2:$G$56,3,FALSE) -> 13044.4 | E5: =VLOOKUP(B5,[1]השוואה!$A$2:$G$56,4,FALSE) -> 0 | F5: =VLOOKUP(B5,[1]השוואה!$A$2:$G$56,5,FALSE) -> 0 | G5: =VLOOKUP(B5,[1]השוואה!$A$2:$G$56,6,FALSE) -> 0 | H5: =VLOOKUP(B5,[1]השוואה!$A$2:$G$56,7,FALSE) -> 0
A6: 91 | B6: 0009 - פרידמן מיכל | C6: =VLOOKUP(B6,[1]השוואה!$A$2:$G$56,2,FALSE) -> 22333.12 | D6: =VLOOKUP(B6,[1]השוואה!$A$2:$G$56,3,FALSE) -> 23348.95 | E6: =VLOOKUP(B6,[1]השוואה!$A$2:$G$56,4,FALSE) -> 18724.41 | F6: =VLOOKUP(B6,[1]השוואה!$A$2:$G$56,5,FALSE) -> 19000.38 | G6: =VLOOKUP(B6,[1]השוואה!$A$2:$G$56,6,FALSE) -> 65410.83 | H6: =VLOOKUP(B6,[1]השוואה!$A$2:$G$56,7,FALSE) -> 0 | I6: =VLOOKUP(A6,[2]השוואה!$A$2:$H$56,8,FALSE) -> 0 | J6: =VLOOKUP(A6,[3]השוואה!$A$2:$J$57,10,FALSE) -> 0 | K6: 0
A7: 109 | B7: 0010 - קובזב מרגריטה | C7: =VLOOKUP(B7,[1]השוואה!$A$2:$G$56,2,FALSE) -> 12286.9 | D7: =VLOOKUP(B7,[1]השוואה!$A$2:$G$56,3,FALSE) -> 14610.73 | E7: =VLOOKUP(B7,[1]השוואה!$A$2:$G$56,4,FALSE) -> 11486.28 | F7: =VLOOKUP(B7,[1]השוואה!$A$2:$G$56,5,FALSE) -> 12472.96 | G7: =VLOOKUP(B7,[1]השוואה!$A$2:$G$56,6,FALSE) -> 13117.94 | H7: =VLOOKUP(B7,[1]השוואה!$A$2:$G$56,7,FALSE) -> 13195.99 | I7: =VLOOKUP(A7,[2]השוואה!$A$2:$H$56,8,FALSE) -> 10931.54 | J7: =VLOOKUP(A7,[3]השוואה!$A$2:$J$57,10,FALSE) -> 12642.23 | K7: 11725.74
A8: 117 | B8: 0011 - הראל טל | C8: =VLOOKUP(B8,[1]השוואה!$A$2:$G$56,2,FALSE) -> 18090.77 | D8: =VLOOKUP(B8,[1]השוואה!$A$2:$G$56,3,FALSE) -> 14816.17 | E8: =VLOOKUP(B8,[1]השוואה!$A$2:$G$56,4,FALSE) -> 18970.3 | F8: =VLOOKUP(B8,[1]השוואה!$A$2:$G$56,5,FALSE) -> 15295.71 | G8: =VLOOKUP(B8,[1]השוואה!$A$2:$G$56,6,FALSE) -> 14534.22 | H8: =VLOOKUP(B8,[1]השוואה!$A$2:$G$56,7,FALSE) -> 16665.64 | I8: =VLOOKUP(A8,[2]השוואה!$A$2:$H$56,8,FALSE) -> 15435.42 | J8: =VLOOKUP(A8,[3]השוואה!$A$2:$J$57,10,FALSE) -> 17723.4 | K8: 21397.59
A9: 125 | B9: 0012 - בסיוני פאוזי | C9: =VLOOKUP(B9,[1]השוואה!$A$2:$G$56,2,FALSE) -> 4859.22 | D9: =VLOOKUP(B9,[1]השוואה!$A$2:$G$56,3,FALSE) -> 11715.02 | E9: =VLOOKUP(B9,[1]השוואה!$A$2:$G$56,4,FALSE) -> 12540.03 | F9: =VLOOKUP(B9,[1]השוואה!$A$2:$G$56,5,FALSE) -> 693.88 | G9: =VLOOKUP(B9,[1]השוואה!$A$2:$G$56,6,FALSE) -> 861.95 | H9: =VLOOKUP(B9,[1]השוואה!$A$2:$G$56,7,FALSE) -> 647.38 | I9: =VLOOKUP(A9,[2]השוואה!$A$2:$H$56,8,FALSE) -> 703.64 | J9: =VLOOKUP(A9,[3]השוואה!$A$2:$J$57,10,FALSE) -> 548.04 | K9: 1193.59
A10: 133 | B10: 0013 - פאר יונית | C10: =VLOOKUP(B10,[1]השוואה!$A$2:$G$56,2,FALSE) -> 19161.32 | D10: =VLOOKUP(B10,[1]השוואה!$A$2:$G$56,3,FALSE) -> 18796.48 | E10: =VLOOKUP(B10,[1]השוואה!$A$2:$G$56,4,FALSE) -> 16975.22 | F10: =VLOOKUP(B10,[1]השוואה!$A$2:$G$56,5,FALSE) -> 15566.24 | G10: =VLOOKUP(B10,[1]השוואה!$A$2:$G$56,6,FALSE) -> 19474.45 | H10: =VLOOKUP(B10,[1]השוואה!$A$2:$G$56,7,FALSE) -> 19087.43 | I10: =VLOOKUP(A10,[2]השוואה!$A$2:$H$56,8,FALSE) -> 20493.82 | J10: =VLOOKUP(A10,[3]השוואה!$A$2:$J$57,10,FALSE) -> 19423.21 | K10: 22310.68
A11: 141 | B11: 0014 - אבידן קינג מלי | C11: =VLOOKUP(B11,[1]השוואה!$A$2:$G$56,2,FALSE) -> 20213.21 | D11: =VLOOKUP(B11,[1]השוואה!$A$2:$G$56,3,FALSE) -> 16563.08 | E11: =VLOOKUP(B11,[1]השוואה!$A$2:$G$56,4,FALSE) -> 2348.67 | F11: =VLOOKUP(B11,[1]השוואה!$A$2:$G$56,5,FALSE) -> 3017.41 | G11: =VLOOKUP(B11,[1]השוואה!$A$2:$G$56,6,FALSE) -> 3459.83 | H11: =VLOOKUP(B11,[1]השוואה!$A$2:$G$56,7,FALSE) -> 3546.64 | I11: =VLOOKUP(A11,[2]השוואה!$A$2:$H$56,8,FALSE) -> 2794.96 | J11: =VLOOKUP(A11,[3]השוואה!$A$2:$J$57,10,FALSE) -> 2879.03 | K11: 2481.65
A12: 182 | B12: 0018 - מזרחי מעיין | C12: =VLOOKUP(B12,[1]השוואה!$A$2:$G$56,2,FALSE) -> 848.83 | D12: =VLOOKUP(B12,[1]השוואה!$A$2:$G$56,3,FALSE) -> 4151.07 | E12: =VLOOKUP(B12,[1]השוואה!$A$2:$G$56,4,FALSE) -> 7608.01 | F12: =VLOOKUP(B12,[1]השוואה!$A$2:$G$56,5,FALSE) -> 10983.57 | G12: =VLOOKUP(B12,[1]השוואה!$A$2:$G$56,6,FALSE) -> 12322.78 | H12: =VLOOKUP(B12,[1]השוואה!$A$2:$G$56,7,FALSE) -> 13265.39 | I12: =VLOOKUP(A12,[2]השוואה!$A$2:$H$56,8,FALSE) -> 12212.56 | J12: =VLOOKUP(A12,[3]השוואה!$A$2:$J$57,10,FALSE) -> 13505.14 | K12: 12479.63
A13: 257 | B13: 0025 - דקל מריה | C13: =VLOOKUP(B13,[1]השוואה!$A$2:$G$56,2,FALSE) -> 18744.65 | D13: =VLOOKUP(B13,[1]השוואה!$A$2:$G$56,3,FALSE) -> 18173.51 | E13: =VLOOKUP(B13,[1]השוואה!$A$2:$G$56,4,FALSE) -> 16640.03 | F13: =VLOOKUP(B13,[1]השוואה!$A$2:$G$56,5,FALSE) -> 16785.18 | G13: =VLOOKUP(B13,[1]השוואה!$A$2:$G$56,6,FALSE) -> 16956.99 | H13: =VLOOKUP(B13,[1]השוואה!$A$2:$G$56,7,FALSE) -> 16111.68 | I13: =VLOOKUP(A13,[2]השוואה!$A$2:$H$56,8,FALSE) -> 16566.19 | J13: =VLOOKUP(A13,[3]השוואה!$A$2:$J$57,10,FALSE) -> 17543.97 | K13: 20973.04
A14: 265 | B14: 0026 - בודאי עומר | C14: =VLOOKUP(B14,[1]השוואה!$A$2:$G$56,2,FALSE) -> 10441.52 | D14: =VLOOKUP(B14,[1]השוואה!$A$2:$G$56,3,FALSE) -> 10097.25 | E14: =VLOOKUP(B14,[1]השוואה!$A$2:$G$56,4,FALSE) -> 9780.49 | F14: =VLOOKUP(B14,[1]השוואה!$A$2:$G$56,5,FALSE) -> 5896.01 | G14: =VLOOKUP(B14,[1]השוואה!$A$2:$G$56,6,FALSE) -> 4985.57 | H14: =VLOOKUP(B14,[1]השוואה!$A$2:$G$56,7,FALSE) -> 0 | I14: =VLOOKUP(A14,[2]השוואה!$A$2:$H$56,8,FALSE) -> 0 | J14: =VLOOKUP(A14,[3]השוואה!$A$2:$J$57,10,FALSE) -> 0 | K14: 0
A15: 281 | B15: 0028 - בריל שלומית | C15: =VLOOKUP(B15,[1]השוואה!$A$2:$G$56,2,FALSE) -> 16838.76 | D15: =VLOOKUP(B15,[1]השוואה!$A$2:$G$56,3,FALSE) -> 18089.62 | E15: =VLOOKUP(B15,[1]השוואה!$A$2:$G$56,4,FALSE) -> 19319.11 | F15: =VLOOKUP(B15,[1]השוואה!$A$2:$G$56,5,FALSE) -> 16238.36 | G15: =VLOOKUP(B15,[1]השוואה!$A$2:$G$56,6,FALSE) -> 29606.87 | H15: =VLOOKUP(B15,[1]השוואה!$A$2:$G$56,7,FALSE) -> 0 | I15: =VLOOKUP(A15,[2]השוואה!$A$2:$H$56,8,FALSE) -> 0 | J15: =VLOOKUP(A15,[3]השוואה!$A$2:$J$57,10,FALSE) -> 0 | K15: 0
A16: 299 | B16: 0029 - שגב נעה | C16: =VLOOKUP(B16,[1]השוואה!$A$2:$G$56,2,FALSE) -> 13072.06 | D16: =VLOOKUP(B16,[1]השוואה!$A$2:$G$56,3,FALSE) -> 7437.69 | E16: =VLOOKUP(B16,[1]השוואה!$A$2:$G$56,4,FALSE) -> 5392.75 | F16: =VLOOKUP(B16,[1]השוואה!$A$2:$G$56,5,FALSE) -> 10789.62 | G16: =VLOOKUP(B16,[1]השוואה!$A$2:$G$56,6,FALSE) -> 7717.57 | H16: =VLOOKUP(B16,[1]השוואה!$A$2:$G$56,7,FALSE) -> 9381.79 | I16: =VLOOKUP(A16,[2]השוואה!$A$2:$H$56,8,FALSE) -> 7523.1 | J16: =VLOOKUP(A16,[3]השוואה!$A$2:$J$57,10,FALSE) -> 22.98 | K16: 3042.86
A17: 349 | B17: 0034 - אור-נזרוב ילנה | C17: =VLOOKUP(B17,[1]השוואה!$A$2:$G$56,2,FALSE) -> 11108.9 | D17: =VLOOKUP(B17,[1]השוואה!$A$2:$G$56,3,FALSE) -> 9388.92 | E17: =VLOOKUP(B17,[1]השוואה!$A$2:$G$56,4,FALSE) -> 9897.84 | F17: =VLOOKUP(B17,[1]השוואה!$A$2:$G$56,5,FALSE) -> 8207.67 | G17: =VLOOKUP(B17,[1]השוואה!$A$2:$G$56,6,FALSE) -> 9223 | H17: =VLOOKUP(B17,[1]השוואה!$A$2:$G$56,7,FALSE) -> 0 | I17: =VLOOKUP(A17,[2]השוואה!$A$2:$H$56,8,FALSE) -> 0 | J17: =VLOOKUP(A17,[3]השוואה!$A$2:$J$57,10,FALSE) -> 0 | K17: 0
A18: 0 | B18: 0038 - גלעדי כליל | C18: =VLOOKUP(B18,[1]השוואה!$A$2:$G$56,2,FALSE) -> 10780.7 | D18: =VLOOKUP(B18,[1]השוואה!$A$2:$G$56,3,FALSE) -> 0 | E18: =VLOOKUP(B18,[1]השוואה!$A$2:$G$56,4,FALSE) -> 0 | F18: =VLOOKUP(B18,[1]השוואה!$A$2:$G$56,5,FALSE) -> 0 | G18: =VLOOKUP(B18,[1]השוואה!$A$2:$G$56,6,FALSE) -> 0 | H18: =VLOOKUP(B18,[1]השוואה!$A$2:$G$56,7,FALSE) -> 0
A19: 414 | B19: 0041 - כהן נאוה | C19: =VLOOKUP(B19,[1]השוואה!$A$2:$G$56,2,FALSE) -> 14153.17 | D19: =VLOOKUP(B19,[1]השוואה!$A$2:$G$56,3,FALSE) -> 12083.28 | E19: =VLOOKUP(B19,[1]השוואה!$A$2:$G$56,4,FALSE) -> 16503.76 | F19: =VLOOKUP(B19,[1]השוואה!$A$2:$G$56,5,FALSE) -> 13670.29 | G19: =VLOOKUP(B19,[1]השוואה!$A$2:$G$56,6,FALSE) -> 13048.08 | H19: =VLOOKUP(B19,[1]השוואה!$A$2:$G$56,7,FALSE) -> 13527.3 | I19: =VLOOKUP(A19,[2]השוואה!$A$2:$H$56,8,FALSE) -> 11651.53 | J19: =VLOOKUP(A19,[3]השוואה!$A$2:$J$57,10,FALSE) -> 15986.39 | K19: 15356.26
A20: 430 | B20: 0043 - שנרך שחף | C20: =VLOOKUP(B20,[1]השוואה!$A$2:$G$56,2,FALSE) -> 17430.62 | D20: =VLOOKUP(B20,[1]השוואה!$A$2:$G$56,3,FALSE) -> 15205.5 | E20: =VLOOKUP(B20,[1]השוואה!$A$2:$G$56,4,FALSE) -> 17869.78 | F20: =VLOOKUP(B20,[1]השוואה!$A$2:$G$56,5,FALSE) -> 17042.81 | G20: =VLOOKUP(B20,[1]השוואה!$A$2:$G$56,6,FALSE) -> 19373.92 | H20: =VLOOKUP(B20,[1]השוואה!$A$2:$G$56,7,FALSE) -> 16762.06 | I20: =VLOOKUP(A20,[2]השוואה!$A$2:$H$56,8,FALSE) -> 8646.49 | J20: =VLOOKUP(A20,[3]השוואה!$A$2:$J$57,10,FALSE) -> 14628.96 | K20: 13283.27
A21: 448 | B21: 0044 - אופק סיוון | C21: =VLOOKUP(B21,[1]השוואה!$A$2:$G$56,2,FALSE) -> 28083.99 | D21: =VLOOKUP(B21,[1]השוואה!$A$2:$G$56,3,FALSE) -> 28607.96 | E21: =VLOOKUP(B21,[1]השוואה!$A$2:$G$56,4,FALSE) -> 23984.6 | F21: =VLOOKUP(B21,[1]השוואה!$A$2:$G$56,5,FALSE) -> 23925.69 | G21: =VLOOKUP(B21,[1]השוואה!$A$2:$G$56,6,FALSE) -> 24367.04 | H21: =VLOOKUP(B21,[1]השוואה!$A$2:$G$56,7,FALSE) -> 32175.9 | I21: =VLOOKUP(A21,[2]השוואה!$A$2:$H$56,8,FALSE) -> 29692.47 | J21: =VLOOKUP(A21,[3]השוואה!$A$2:$J$57,10,FALSE) -> 28925.24 | K21: 28902.27
A22: 463 | B22: 0046 - שמואלוביץ מיטל | C22: =VLOOKUP(B22,[1]השוואה!$A$2:$G$56,2,FALSE) -> 10820.19 | D22: =VLOOKUP(B22,[1]השוואה!$A$2:$G$56,3,FALSE) -> 9278.97 | E22: =VLOOKUP(B22,[1]השוואה!$A$2:$G$56,4,FALSE) -> 6869.92 | F22: =VLOOKUP(B22,[1]השוואה!$A$2:$G$56,5,FALSE) -> 10709.55 | G22: =VLOOKUP(B22,[1]השוואה!$A$2:$G$56,6,FALSE) -> 18621.7 | H22: =VLOOKUP(B22,[1]השוואה!$A$2:$G$56,7,FALSE) -> 0 | I22: =VLOOKUP(A22,[2]השוואה!$A$2:$H$56,8,FALSE) -> 0 | J22: =VLOOKUP(A22,[3]השוואה!$A$2:$J$57,10,FALSE) -> 0 | K22: 0
A23: 471 | B23: 0047 - זלינגר עמית | C23: =VLOOKUP(B23,[1]השוואה!$A$2:$G$56,2,FALSE) -> 20645.98 | D23: =VLOOKUP(B23,[1]השוואה!$A$2:$G$56,3,FALSE) -> 22066.73 | E23: =VLOOKUP(B23,[1]השוואה!$A$2:$G$56,4,FALSE) -> 21593.79 | F23: =VLOOKUP(B23,[1]השוואה!$A$2:$G$56,5,FALSE) -> 26507.17 | G23: =VLOOKUP(B23,[1]השוואה!$A$2:$G$56,6,FALSE) -> 22837.82 | H23: =VLOOKUP(B23,[1]השוואה!$A$2:$G$56,7,FALSE) -> 24862.96 | I23: =VLOOKUP(A23,[2]השוואה!$A$2:$H$56,8,FALSE) -> 22606.91 | J23: =VLOOKUP(A23,[3]השוואה!$A$2:$J$57,10,FALSE) -> 16289.11 | K23: 25464.32
A24: 489 | B24: 0048 - שרוי מאי | C24: =VLOOKUP(B24,[1]השוואה!$A$2:$G$56,2,FALSE) -> 17485.24 | D24: =VLOOKUP(B24,[1]השוואה!$A$2:$G$56,3,FALSE) -> 16233.08 | E24: =VLOOKUP(B24,[1]השוואה!$A$2:$G$56,4,FALSE) -> 14117.51 | F24: =VLOOKUP(B24,[1]השוואה!$A$2:$G$56,5,FALSE) -> 16621.03 | G24: =VLOOKUP(B24,[1]השוואה!$A$2:$G$56,6,FALSE) -> 14181.44 | H24: =VLOOKUP(B24,[1]השוואה!$A$2:$G$56,7,FALSE) -> 12808.16 | I24: =VLOOKUP(A24,[2]השוואה!$A$2:$H$56,8,FALSE) -> 0 | J24: =VLOOKUP(A24,[3]השוואה!$A$2:$J$57,10,FALSE) -> 3040.76 | K24: 16472.17
A25: 513 | B25: 0051 - סלבין עדן | C25: =VLOOKUP(B25,[1]השוואה!$A$2:$G$56,2,FALSE) -> 6248.76 | D25: =VLOOKUP(B25,[1]השוואה!$A$2:$G$56,3,FALSE) -> 7741.7 | E25: =VLOOKUP(B25,[1]השוואה!$A$2:$G$56,4,FALSE) -> 6447.49 | F25: =VLOOKUP(B25,[1]השוואה!$A$2:$G$56,5,FALSE) -> 7284.5 | G25: =VLOOKUP(B25,[1]השוואה!$A$2:$G$56,6,FALSE) -> 7083.7 | H25: =VLOOKUP(B25,[1]השוואה!$A$2:$G$56,7,FALSE) -> 5505.5 | I25: =VLOOKUP(A25,[2]השוואה!$A$2:$H$56,8,FALSE) -> 3792.43 | J25: =VLOOKUP(A25,[3]השוואה!$A$2:$J$57,10,FALSE) -> 7247.5 | K25: 7403.73
A26: 0 | B26: 0057 - אביבי נופר | C26: =VLOOKUP(B26,[1]השוואה!$A$2:$G$56,2,FALSE) -> 11620.06 | D26: =VLOOKUP(B26,[1]השוואה!$A$2:$G$56,3,FALSE) -> 5962.13 | E26: =VLOOKUP(B26,[1]השוואה!$A$2:$G$56,4,FALSE) -> 12365.36 | F26: =VLOOKUP(B26,[1]השוואה!$A$2:$G$56,5,FALSE) -> 0 | G26: =VLOOKUP(B26,[1]השוואה!$A$2:$G$56,6,FALSE) -> 0 | H26: =VLOOKUP(B26,[1]השוואה!$A$2:$G$56,7,FALSE) -> 0
A27: 588 | B27: 0058 - תומפסון ג'וסלין | C27: =VLOOKUP(B27,[1]השוואה!$A$2:$G$56,2,FALSE) -> 7687.32 | D27: =VLOOKUP(B27,[1]השוואה!$A$2:$G$56,3,FALSE) -> 10614.31 | E27: =VLOOKUP(B27,[1]השוואה!$A$2:$G$56,4,FALSE) -> 7239.91 | F27: =VLOOKUP(B27,[1]השוואה!$A$2:$G$56,5,FALSE) -> 11452.79 | G27: =VLOOKUP(B27,[1]השוואה!$A$2:$G$56,6,FALSE) -> 10105.3 | H27: =VLOOKUP(B27,[1]השוואה!$A$2:$G$56,7,FALSE) -> 14049.41 | I27: =VLOOKUP(A27,[2]השוואה!$A$2:$H$56,8,FALSE) -> 9992.45 | J27: =VLOOKUP(A27,[3]השוואה!$A$2:$J$57,10,FALSE) -> 14930.99 | K27: 13224.18
A28: 604 | B28: 0060 - גלפנד אביגיל | C28: =VLOOKUP(B28,[1]השוואה!$A$2:$G$56,2,FALSE) -> 9453.49 | D28: =VLOOKUP(B28,[1]השוואה!$A$2:$G$56,3,FALSE) -> 8896.16 | E28: =VLOOKUP(B28,[1]השוואה!$A$2:$G$56,4,FALSE) -> 6643.73 | F28: =VLOOKUP(B28,[1]השוואה!$A$2:$G$56,5,FALSE) -> 7337.47 | G28: =VLOOKUP(B28,[1]השוואה!$A$2:$G$56,6,FALSE) -> 7715.44 | H28: =VLOOKUP(B28,[1]השוואה!$A$2:$G$56,7,FALSE) -> 7713.35 | I28: =VLOOKUP(A28,[2]השוואה!$A$2:$H$56,8,FALSE) -> 5904.14 | J28: =VLOOKUP(A28,[3]השוואה!$A$2:$J$57,10,FALSE) -> 3413.96 | K28: 4476
A29: 612 | B29: 0061 - שדאד ג'ורג' | C29: =VLOOKUP(B29,[1]השוואה!$A$2:$G$56,2,FALSE) -> 29825.01 | D29: =VLOOKUP(B29,[1]השוואה!$A$2:$G$56,3,FALSE) -> 0 | E29: =VLOOKUP(B29,[1]השוואה!$A$2:$G$56,4,FALSE) -> 0 | F29: =VLOOKUP(B29,[1]השוואה!$A$2:$G$56,5,FALSE) -> 0 | G29: =VLOOKUP(B29,[1]השוואה!$A$2:$G$56,6,FALSE) -> 19435.31 | H29: =VLOOKUP(B29,[1]השוואה!$A$2:$G$56,7,FALSE) -> 24949.28 | I29: =VLOOKUP(A29,[2]השוואה!$A$2:$H$56,8,FALSE) -> 24197.6 | J29: =VLOOKUP(A29,[3]השוואה!$A$2:$J$57,10,FALSE) -> 25586.51 | K29: 28048.75
A30: 0 | B30: 0063 - זיני דניאל | C30: =VLOOKUP(B30,[1]השוואה!$A$2:$G$56,2,FALSE) -> 7778.84 | D30: =VLOOKUP(B30,[1]השוואה!$A$2:$G$56,3,FALSE) -> 0 | E30: =VLOOKUP(B30,[1]השוואה!$A$2:$G$56,4,FALSE) -> 0 | F30: =VLOOKUP(B30,[1]השוואה!$A$2:$G$56,5,FALSE) -> 0 | G30: =VLOOKUP(B30,[1]השוואה!$A$2:$G$56,6,FALSE) -> 0 | H30: =VLOOKUP(B30,[1]השוואה!$A$2:$G$56,7,FALSE) -> 0
A31: 0 | B31: 0064 - מימון-לידר דפנה | C31: =VLOOKUP(B31,[1]השוואה!$A$2:$G$56,2,FALSE) -> 20078.05 | D31: =VLOOKUP(B31,[1]השוואה!$A$2:$G$56,3,FALSE) -> 19035.56 | E31: =VLOOKUP(B31,[1]השוואה!$A$2:$G$56,4,FALSE) -> 15698.24 | F31: =VLOOKUP(B31,[1]השוואה!$A$2:$G$56,5,FALSE) -> 0 | G31: =VLOOKUP(B31,[1]השוואה!$A$2:$G$56,6,FALSE) -> 0 | H31: =VLOOKUP(B31,[1]השוואה!$A$2:$G$56,7,FALSE) -> 0
A32: 653 | B32: 0065 - גובר יריב | C32: =VLOOKUP(B32,[1]השוואה!$A$2:$G$56,2,FALSE) -> 30865.91 | D32: =VLOOKUP(B32,[1]השוואה!$A$2:$G$56,3,FALSE) -> 29671.47 | E32: =VLOOKUP(B32,[1]השוואה!$A$2:$G$56,4,FALSE) -> 30745.06 | F32: =VLOOKUP(B32,[1]השוואה!$A$2:$G$56,5,FALSE) -> 28784.92 | G32: =VLOOKUP(B32,[1]השוואה!$A$2:$G$56,6,FALSE) -> 26978.56 | H32: =VLOOKUP(B32,[1]השוואה!$A$2:$G$56,7,FALSE) -> 27826.52 | I32: =VLOOKUP(A32,[2]השוואה!$A$2:$H$56,8,FALSE) -> 26113.65 | J32: =VLOOKUP(A32,[3]השוואה!$A$2:$J$57,10,FALSE) -> 29520.01 | K32: 30935.53
A33: 679 | B33: 0067 - עוזיאל עידן יעקב | C33: =VLOOKUP(B33,[1]השוואה!$A$2:$G$56,2,FALSE) -> 28551.74 | D33: =VLOOKUP(B33,[1]השוואה!$A$2:$G$56,3,FALSE) -> 36487.17 | E33: =VLOOKUP(B33,[1]השוואה!$A$2:$G$56,4,FALSE) -> 31033.3 | F33: =VLOOKUP(B33,[1]השוואה!$A$2:$G$56,5,FALSE) -> 29854.78 | G33: =VLOOKUP(B33,[1]השוואה!$A$2:$G$56,6,FALSE) -> 27548.33 | H33: =VLOOKUP(B33,[1]השוואה!$A$2:$G$56,7,FALSE) -> 30887.88 | I33: =VLOOKUP(A33,[2]השוואה!$A$2:$H$56,8,FALSE) -> 27961.89 | J33: =VLOOKUP(A33,[3]השוואה!$A$2:$J$57,10,FALSE) -> 26655.82 | K33: 30790.45
A34: 695 | B34: 0069 - גרבשקוב וסיליסה | C34: =VLOOKUP(B34,[1]השוואה!$A$2:$G$56,2,FALSE) -> 12117.5 | D34: =VLOOKUP(B34,[1]השוואה!$A$2:$G$56,3,FALSE) -> 11601.76 | E34: =VLOOKUP(B34,[1]השוואה!$A$2:$G$56,4,FALSE) -> 12682.99 | F34: =VLOOKUP(B34,[1]השוואה!$A$2:$G$56,5,FALSE) -> 8918.82 | G34: =VLOOKUP(B34,[1]השוואה!$A$2:$G$56,6,FALSE) -> 10634.47 | H34: =VLOOKUP(B34,[1]השוואה!$A$2:$G$56,7,FALSE) -> 8884.85 | I34: =VLOOKUP(A34,[2]השוואה!$A$2:$H$56,8,FALSE) -> 9449.85 | J34: =VLOOKUP(A34,[3]השוואה!$A$2:$J$57,10,FALSE) -> 8945.06 | K34: 10693.01
A35: 703 | B35: 0070 - חיריק אור | C35: =VLOOKUP(B35,[1]השוואה!$A$2:$G$56,2,FALSE) -> 7087.66 | D35: =VLOOKUP(B35,[1]השוואה!$A$2:$G$56,3,FALSE) -> 8232.74 | E35: =VLOOKUP(B35,[1]השוואה!$A$2:$G$56,4,FALSE) -> 9448.14 | F35: =VLOOKUP(B35,[1]השוואה!$A$2:$G$56,5,FALSE) -> 6501.91 | G35: =VLOOKUP(B35,[1]השוואה!$A$2:$G$56,6,FALSE) -> 5839.89 | H35: =VLOOKUP(B35,[1]השוואה!$A$2:$G$56,7,FALSE) -> 6620.88 | I35: =VLOOKUP(A35,[2]השוואה!$A$2:$H$56,8,FALSE) -> 4973.7 | J35: =VLOOKUP(A35,[3]השוואה!$A$2:$J$57,10,FALSE) -> 8710.01 | K35: 8972.94
A36: 729 | B36: 0072 - גוטמן רחל לאה | C36: =VLOOKUP(B36,[1]השוואה!$A$2:$G$56,2,FALSE) -> 13672.86 | D36: =VLOOKUP(B36,[1]השוואה!$A$2:$G$56,3,FALSE) -> 11405.16 | E36: =VLOOKUP(B36,[1]השוואה!$A$2:$G$56,4,FALSE) -> 15958.3 | F36: =VLOOKUP(B36,[1]השוואה!$A$2:$G$56,5,FALSE) -> 12666.62 | G36: =VLOOKUP(B36,[1]השוואה!$A$2:$G$56,6,FALSE) -> 4326.41 | H36: =VLOOKUP(B36,[1]השוואה!$A$2:$G$56,7,FALSE) -> 7824.79 | I36: =VLOOKUP(A36,[2]השוואה!$A$2:$H$56,8,FALSE) -> 12147.07 | J36: =VLOOKUP(A36,[3]השוואה!$A$2:$J$57,10,FALSE) -> 0 | K36: 0
A37: 745 | B37: 0074 - קוטליארוב ניקול | C37: =VLOOKUP(B37,[1]השוואה!$A$2:$G$56,2,FALSE) -> 11961.92 | D37: =VLOOKUP(B37,[1]השוואה!$A$2:$G$56,3,FALSE) -> 14220.52 | E37: =VLOOKUP(B37,[1]השוואה!$A$2:$G$56,4,FALSE) -> 11868.09 | F37: =VLOOKUP(B37,[1]השוואה!$A$2:$G$56,5,FALSE) -> 12844.62 | G37: =VLOOKUP(B37,[1]השוואה!$A$2:$G$56,6,FALSE) -> 12434.76 | H37: =VLOOKUP(B37,[1]השוואה!$A$2:$G$56,7,FALSE) -> 11088.04 | I37: =VLOOKUP(A37,[2]השוואה!$A$2:$H$56,8,FALSE) -> 9040.57 | J37: =VLOOKUP(A37,[3]השוואה!$A$2:$J$57,10,FALSE) -> 11034.23 | K37: 12635.11
A38: 752 | B38: 0075 - רפאל שיר | C38: =VLOOKUP(B38,[1]השוואה!$A$2:$G$56,2,FALSE) -> 6139.82 | D38: =VLOOKUP(B38,[1]השוואה!$A$2:$G$56,3,FALSE) -> 11384.09 | E38: =VLOOKUP(B38,[1]השוואה!$A$2:$G$56,4,FALSE) -> 12488.32 | F38: =VLOOKUP(B38,[1]השוואה!$A$2:$G$56,5,FALSE) -> 11029.21 | G38: =VLOOKUP(B38,[1]השוואה!$A$2:$G$56,6,FALSE) -> 10925.11 | H38: =VLOOKUP(B38,[1]השוואה!$A$2:$G$56,7,FALSE) -> 11186.81 | I38: =VLOOKUP(A38,[2]השוואה!$A$2:$H$56,8,FALSE) -> 10042.74 | J38: =VLOOKUP(A38,[3]השוואה!$A$2:$J$57,10,FALSE) -> 9578.22 | K38: 12903.35
